Workbook
Name \a: #REF!
Name \a: #REF!
Name \p: #REF!
Name \p: #REF!
Name ____________z2: {"Sch00",#N/A,FALSE,"1";"Contents",#N/A,FALSE,"1"}
Name ____________z2: {"Sch00",#N/A,FALSE,"1";"Contents",#N/A,FALSE,"1"}
Name ___________z2: {"Sch00",#N/A,FALSE,"1";"Contents",#N/A,FALSE,"1"}
Name ___________z2: {"Sch00",#N/A,FALSE,"1";"Contents",#N/A,FALSE,"1"}
Name __________z2: {"Sch00",#N/A,FALSE,"1";"Contents",#N/A,FALSE,"1"}
Name __________z2: {"Sch00",#N/A,FALSE,"1";"Contents",#N/A,FALSE,"1"}
Name _________key1: #REF!
Name _________PL2: {#N/A,#N/A,FALSE,"Aging Summary";#N/A,#N/A,FALSE,"Ratio Analysis";#N/A,#N/A,FALSE,"Test 120 Day Accts";#N/A,#N/A,FALSE,"Tickmarks"}
Name _________PL2: {#N/A,#N/A,FALSE,"Aging Summary";#N/A,#N/A,FALSE,"Ratio Analysis";#N/A,#N/A,FALSE,"Test 120 Day Accts";#N/A,#N/A,FALSE,"Tickmarks"}
Name _________w2: {"HİZDAFİŞ",#N/A,FALSE,"YDYUKLE"}
Name _________w2: {"HİZDAFİŞ",#N/A,FALSE,"YDYUKLE"}
Name _________z2: {"Sch00",#N/A,FALSE,"1";"Contents",#N/A,FALSE,"1"}
Name _________z2: {"Sch00",#N/A,FALSE,"1";"Contents",#N/A,FALSE,"1"}
Name ________c: {"Fiesta Facer Page",#N/A,FALSE,"Q_C_S";"Fiesta Main Page",#N/A,FALSE,"V_L";"Fiesta 95BP Struct",#N/A,FALSE,"StructBP";"Fiesta Post 95BP Struct",#N/A,FALSE,"AdjStructBP"}
Name ________c: {"Fiesta Facer Page",#N/A,FALSE,"Q_C_S";"Fiesta Main Page",#N/A,FALSE,"V_L";"Fiesta 95BP Struct",#N/A,FALSE,"StructBP";"Fiesta Post 95BP Struct",#N/A,FALSE,"AdjStructBP"}
Name ________key1: #REF!
Name ________key1: #REF!
Name ________PL2: {#N/A,#N/A,FALSE,"Aging Summary";#N/A,#N/A,FALSE,"Ratio Analysis";#N/A,#N/A,FALSE,"Test 120 Day Accts";#N/A,#N/A,FALSE,"Tickmarks"}
Name ________PL2: {#N/A,#N/A,FALSE,"Aging Summary";#N/A,#N/A,FALSE,"Ratio Analysis";#N/A,#N/A,FALSE,"Test 120 Day Accts";#N/A,#N/A,FALSE,"Tickmarks"}
Name ________w1: #REF!
Name ________w1: #REF!
Name ________w2: {"HİZDAFİŞ",#N/A,FALSE,"YDYUKLE"}
Name ________w2: {"HİZDAFİŞ",#N/A,FALSE,"YDYUKLE"}
Name ________z2: {"Sch00",#N/A,FALSE,"1";"Contents",#N/A,FALSE,"1"}
Name ________z2: {"Sch00",#N/A,FALSE,"1";"Contents",#N/A,FALSE,"1"}
Name _______A1: {#N/A,#N/A,FALSE,"MALİTABLOLAR"}
Name _______A1: {#N/A,#N/A,FALSE,"MALİTABLOLAR"}
Name _______c: {"Fiesta Facer Page",#N/A,FALSE,"Q_C_S";"Fiesta Main Page",#N/A,FALSE,"V_L";"Fiesta 95BP Struct",#N/A,FALSE,"StructBP";"Fiesta Post 95BP Struct",#N/A,FALSE,"AdjStructBP"}
Name _______c: {"Fiesta Facer Page",#N/A,FALSE,"Q_C_S";"Fiesta Main Page",#N/A,FALSE,"V_L";"Fiesta 95BP Struct",#N/A,FALSE,"StructBP";"Fiesta Post 95BP Struct",#N/A,FALSE,"AdjStructBP"}
Name _______key1: #REF!
Name _______key1: #REF!
Name _______PL2: {#N/A,#N/A,FALSE,"Aging Summary";#N/A,#N/A,FALSE,"Ratio Analysis";#N/A,#N/A,FALSE,"Test 120 Day Accts";#N/A,#N/A,FALSE,"Tickmarks"}
Name _______PL2: {#N/A,#N/A,FALSE,"Aging Summary";#N/A,#N/A,FALSE,"Ratio Analysis";#N/A,#N/A,FALSE,"Test 120 Day Accts";#N/A,#N/A,FALSE,"Tickmarks"}
Name _______w1: #REF!
Name _______w1: #REF!
Name _______w2: {"HİZDAFİŞ",#N/A,FALSE,"YDYUKLE"}
Name _______w2: {"HİZDAFİŞ",#N/A,FALSE,"YDYUKLE"}
Name _______z2: {"Sch00",#N/A,FALSE,"1";"Contents",#N/A,FALSE,"1"}
Name _______z2: {"Sch00",#N/A,FALSE,"1";"Contents",#N/A,FALSE,"1"}
Name ______c: {"Fiesta Facer Page",#N/A,FALSE,"Q_C_S";"Fiesta Main Page",#N/A,FALSE,"V_L";"Fiesta 95BP Struct",#N/A,FALSE,"StructBP";"Fiesta Post 95BP Struct",#N/A,FALSE,"AdjStructBP"}
Name ______c: {"Fiesta Facer Page",#N/A,FALSE,"Q_C_S";"Fiesta Main Page",#N/A,FALSE,"V_L";"Fiesta 95BP Struct",#N/A,FALSE,"StructBP";"Fiesta Post 95BP Struct",#N/A,FALSE,"AdjStructBP"}
Name ______d: {"Fiesta Facer Page",#N/A,FALSE,"Q_C_S";"Fiesta Main Page",#N/A,FALSE,"V_L";"Fiesta 95BP Struct",#N/A,FALSE,"StructBP";"Fiesta Post 95BP Struct",#N/A,FALSE,"AdjStructBP"}
Name ______d: {"Fiesta Facer Page",#N/A,FALSE,"Q_C_S";"Fiesta Main Page",#N/A,FALSE,"V_L";"Fiesta 95BP Struct",#N/A,FALSE,"StructBP";"Fiesta Post 95BP Struct",#N/A,FALSE,"AdjStructBP"}
Name ______key1: #REF!
Name ______key1: #REF!
Name ______PL2: {#N/A,#N/A,FALSE,"Aging Summary";#N/A,#N/A,FALSE,"Ratio Analysis";#N/A,#N/A,FALSE,"Test 120 Day Accts";#N/A,#N/A,FALSE,"Tickmarks"}
Name ______PL2: {#N/A,#N/A,FALSE,"Aging Summary";#N/A,#N/A,FALSE,"Ratio Analysis";#N/A,#N/A,FALSE,"Test 120 Day Accts";#N/A,#N/A,FALSE,"Tickmarks"}
Name ______w1: #REF!
Name ______w1: #REF!
Name ______w2: {"HİZDAFİŞ",#N/A,FALSE,"YDYUKLE"}
Name ______w2: {"HİZDAFİŞ",#N/A,FALSE,"YDYUKLE"}
Name ______z2: {"Sch00",#N/A,FALSE,"1";"Contents",#N/A,FALSE,"1"}
Name ______z2: {"Sch00",#N/A,FALSE,"1";"Contents",#N/A,FALSE,"1"}
Name _____A1: {#N/A,#N/A,FALSE,"MALİTABLOLAR"}
Name _____A1: {#N/A,#N/A,FALSE,"MALİTABLOLAR"}
Name _____key1: #REF!

Sheet Consolidated ARR Rollforward
B2: Trio Mobil
B3: Consolidated ARR Rollforward
C5: =C6&" " &YEAR(C8) -> Q4 2021 | D5: =D6&" " &YEAR(D8) -> Q4 2022 | E5: =E6&" " &YEAR(E8) -> Q4 2023 | F5: =F6&" " &YEAR(F8) -> Q4 2024 | G5: =G6&" " &YEAR(G8) -> TTM 2025 | I5: =I6&" " &YEAR(I8) -> Q1 2021 | J5: =J6&" " &YEAR(J8) -> Q2 2021 | K5: =K6&" " &YEAR(K8) -> Q3 2021 | L5: =L6&" " &YEAR(L8) -> Q4 2021 | M5: =M6&" " &YEAR(M8) -> Q1 2022 | N5: =N6&" " &YEAR(N8) -> Q2 2022 | O5: =O6&" " &YEAR(O8) -> Q3 2022 | P5: =P6&" " &YEAR(P8) -> Q4 2022 | ... AB5: =AB6&" " &YEAR(AB8) -> Q4 2025 | AD5: =AD6&" " &YEAR(AD8) -> Q1 2021 | AE5: =AE6&" " &YEAR(AE8) -> Q1 2021 | AF5: =AF6&" " &YEAR(AF8) -> Q1 2021 | AG5: =AG6&" " &YEAR(AG8) -> Q2 2021 | AH5: =AH6&" " &YEAR(AH8) -> Q2 2021 | AI5: =AI6&" " &YEAR(AI8) -> Q2 2021 | AJ5: =AJ6&" " &YEAR(AJ8) -> Q3 2021 | AK5: =AK6&" " &YEAR(AK8) -> Q3 2021 | ... CK5: =CK6&" " &YEAR(CK8) -> Q4 2025
C6: Q4 | D6: Q4 | E6: Q4 | F6: Q4 | G6: TTM | I6: Q1 | J6: Q2 | K6: Q3 | L6: Q4 | M6: Q1 | N6: Q2 | O6: Q3 | P6: Q4 | Q6: Q1 | R6: Q2 | S6: Q3 | T6: Q4 | U6: Q1 | V6: Q2 | W6: Q3 | X6: Q4 | Y6: Q1 | Z6: Q2 | AA6: Q3 | AB6: Q4 | AD6: Q1 | AE6: Q1 | AF6: Q1 | AG6: Q2 | AH6: Q2 | AI6: Q2 | AJ6: Q3 | AK6: Q3 | AL6: Q3 | AM6: Q4 | AN6: Q4 | AO6: Q4 | AP6: Q1 | AQ6: Q1 | AR6: Q1 | AS6: Q2 | AT6: Q2 | AU6: Q2 | AV6: Q3 | AW6: Q3 | AX6: Q3 | AY6: Q4 | AZ6: Q4 | BA6: Q4 | BB6: Q1 | BC6: Q1 | BD6: Q1 | BE6: Q2 | BF6: Q2 | BG6: Q2 | BH6: Q3 | BI6: Q3 | BJ6: Q3 | BK6: Q4 | BL6: Q4 | BM6: Q4 | BN6: Q1 | BO6: Q1 | BP6: Q1 | BQ6: Q2 | BR6: Q2 | BS6: Q2 | BT6: Q3 | BU6: Q3 | BV6: Q3 | BW6: Q4 | BX6: Q4 | BY6: Q4 | BZ6: Q1 | CA6: Q1 | CB6: Q1 | CC6: Q2 | CD6: Q2 | CE6: Q2 | CF6: Q3 | CG6: Q3 | CH6: Q3 | CI6: Q4 | CJ6: Q4 | CK6: Q4
C7: =YEAR(C8) -> 2021 | D7: =YEAR(D8) -> 2022 | E7: =YEAR(E8) -> 2023 | F7: =YEAR(F8) -> 2024 | G7: =YEAR(G8) -> 2025 | I7: =YEAR(I8) -> 2021 | J7: =YEAR(J8) -> 2021 | K7: =YEAR(K8) -> 2021 | L7: =YEAR(L8) -> 2021 | M7: =YEAR(M8) -> 2022 | N7: =YEAR(N8) -> 2022 | O7: =YEAR(O8) -> 2022 | P7: =YEAR(P8) -> 2022 | ... AB7: =YEAR(AB8) -> 2025 | AD7: =YEAR(AD8) -> 2021 | AE7: =YEAR(AE8) -> 2021 | AF7: =YEAR(AF8) -> 2021 | AG7: =YEAR(AG8) -> 2021 | AH7: =YEAR(AH8) -> 2021 | AI7: =YEAR(AI8) -> 2021 | AJ7: =YEAR(AJ8) -> 2021 | AK7: =YEAR(AK8) -> 2021 | ... CK7: =YEAR(CK8) -> 2025
B8: Consolidated | C8: 44561 | D8: =EOMONTH(C8,12) -> 44926 | E8: =EOMONTH(D8,12) -> 45291 | F8: =EOMONTH(E8,12) -> 45657 | G8: =EOMONTH(F8,12) -> 46022 | I8: 44286 | J8: =EOMONTH(I8,3) -> 44377 | K8: =EOMONTH(J8,3) -> 44469 | L8: =EOMONTH(K8,3) -> 44561 | M8: =EOMONTH(L8,3) -> 44651 | N8: =EOMONTH(M8,3) -> 44742 | O8: =EOMONTH(N8,3) -> 44834 | P8: =EOMONTH(O8,3) -> 44926 | Q8: =EOMONTH(P8,3) -> 45016 | ... V8: =EOMONTH(U8,3) -> 45473 | W8: 45565 | X8: 45657 | Y8: 45747 | Z8: 45838 | AA8: 45930 | AB8: 46022 | AD8: 44227 | AE8: =EOMONTH(AD8,1) -> 44255 | AF8: =EOMONTH(AE8,1) -> 44286 | AG8: =EOMONTH(AF8,1) -> 44316 | AH8: =EOMONTH(AG8,1) -> 44347 | AI8: =EOMONTH(AH8,1) -> 44377 | AJ8: =EOMONTH(AI8,1) -> 44408 | AK8: =EOMONTH(AJ8,1) -> 44439 | AL8: =EOMONTH(AK8,1) -> 44469 | ... CK8: =EOMONTH(CJ8,1) -> 46022
B9: Beginning | C9: =I9 -> 715138.93 | D9: =+SUMIFS($AD$14:$CF$14,$AD$8:$CF$8,EOMONTH(D8,-12)) -> 3507271 | E9: =+SUMIFS($AD$14:$CF$14,$AD$8:$CF$8,EOMONTH(E8,-12)) -> 5002928.5 | F9: =+SUMIFS($AD$14:$CF$14,$AD$8:$CF$8,EOMONTH(F8,-12)) -> 8109284.5 | G9: =+SUMIFS($AD$14:$CL$14,$AD$8:$CL$8,EOMONTH(G8,-12)) -> 12126892 | I9: =AD9 -> 715138.93 | J9: =I14 -> 3495929.7 | K9: =J14 -> 3452428.7 | L9: =K14 -> 3577856.3 | M9: =L14 -> 3507271 | N9: =M14 -> 3631952.4 | O9: =N14 -> 4203281.2 | P9: =O14 -> 4549342.6 | Q9: =P14 -> 5002928.5 | ... AB9: =AA14 -> 15273205 | AD9: ='Industrial ARR Rollforward'!AD9+'Fleet ARR Rollforward'!AD9 -> 715138.93 | AE9: ='Industrial ARR Rollforward'!AE9+'Fleet ARR Rollforward'!AE9 -> 3529580 | AF9: ='Industrial ARR Rollforward'!AF9+'Fleet ARR Rollforward'!AF9 -> 3528617.5 | AG9: ='Industrial ARR Rollforward'!AG9+'Fleet ARR Rollforward'!AG9 -> 3495929.7 | AH9: ='Industrial ARR Rollforward'!AH9+'Fleet ARR Rollforward'!AH9 -> 3493397.3 | AI9: ='Industrial ARR Rollforward'!AI9+'Fleet ARR Rollforward'!AI9 -> 3449599.5 | AJ9: ='Industrial ARR Rollforward'!AJ9+'Fleet ARR Rollforward'!AJ9 -> 3452428.7 | AK9: ='Industrial ARR Rollforward'!AK9+'Fleet ARR Rollforward'!AK9 -> 3405075 | ... CK9: ='Industrial ARR Rollforward'!CK9+'Fleet ARR Rollforward'!CK9 -> 15617061
B10: (+) New | C10: =SUMIFS($I10:$W10,$I$7:$W$7,C$7) -> 3400161.7 | D10: =+SUM(OFFSET(INDEX($AD10:$CF10,MATCH(D$8,$AD$8:$CF$8,0)),,,,-12)) -> 1165365.2 | E10: =+SUM(OFFSET(INDEX($AD10:$CF10,MATCH(E$8,$AD$8:$CF$8,0)),,,,-12)) -> 1954185 | F10: =+SUM(OFFSET(INDEX($AD10:$CF10,MATCH(F$8,$AD$8:$CF$8,0)),,,,-12)) -> 1964300.1 | G10: =+SUM(OFFSET(INDEX($AD10:$CL10,MATCH(G$8,$AD$8:$CL$8,0)),,,,-12)) -> 3557396.4 | I10: =SUMIFS($AD10:$BT10,$AD$5:$BT$5,I$5) -> 2870278.7 | J10: =SUMIFS($AD10:$BT10,$AD$5:$BT$5,J$5) -> 101821.64 | K10: =SUMIFS($AD10:$BT10,$AD$5:$BT$5,K$5) -> 234100.68 | L10: =SUMIFS($AD10:$BT10,$AD$5:$BT$5,L$5) -> 193960.62 | M10: =SUMIFS($AD10:$BT10,$AD$5:$BT$5,M$5) -> 150751.61 | N10: =SUMIFS($AD10:$BT10,$AD$5:$BT$5,N$5) -> 493235.1 | O10: =SUMIFS($AD10:$BT10,$AD$5:$BT$5,O$5) -> 273237.78 | P10: =SUMIFS($AD10:$BT10,$AD$5:$BT$5,P$5) -> 248140.68 | ... V10: =SUMIFS($AD10:$BT10,$AD$5:$BT$5,V$5) -> 544603.79 | W10: =SUMIFS($AD10:$CF10,$AD$5:$CF$5,W$5) -> 310214.83 | X10: =SUMIFS($AD10:$CF10,$AD$5:$CF$5,X$5) -> 687632.42 | Y10: =SUMIFS($AD10:$CF10,$AD$5:$CF$5,Y$5) -> 1197487.5 | Z10: =SUMIFS($AD10:$CF10,$AD$5:$CF$5,Z$5) -> 721391.07 | AA10: =SUMIFS($AD10:$CL10,$AD$5:$CL$5,AA$5) -> 700150.82 | AB10: =SUMIFS($AD10:$CL10,$AD$5:$CL$5,AB$5) -> 938367.02 | AD10: ='Industrial ARR Rollforward'!AD10+'Fleet ARR Rollforward'!AD10 -> 2787519.2 | AE10: ='Industrial ARR Rollforward'!AE10+'Fleet ARR Rollforward'!AE10 -> 47145.806 | AF10: ='Industrial ARR Rollforward'!AF10+'Fleet ARR Rollforward'!AF10 -> 35613.696 | AG10: ='Industrial ARR Rollforward'!AG10+'Fleet ARR Rollforward'!AG10 -> 36724.558 | AH10: ='Industrial ARR Rollforward'!AH10+'Fleet ARR Rollforward'!AH10 -> 23508.482 | AI10: ='Industrial ARR Rollforward'!AI10+'Fleet ARR Rollforward'!AI10 -> 41588.602 | AJ10: ='Industrial ARR Rollforward'!AJ10+'Fleet ARR Rollforward'!AJ10 -> 41493.194 | AK10: ='Industrial ARR Rollforward'!AK10+'Fleet ARR Rollforward'!AK10 -> 69799.236 | ... CK10: ='Industrial ARR Rollforward'!CK10+'Fleet ARR Rollforward'!CK10 -> 620438.57
B11: (+) Upsell | C11: =SUMIFS($I11:$W11,$I$7:$W$7,C$7) -> 780822.36 | D11: =+SUM(OFFSET(INDEX($AD11:$CF11,MATCH(D$8,$AD$8:$CF$8,0)),,,,-12)) -> 1631159.5 | E11: =+SUM(OFFSET(INDEX($AD11:$CF11,MATCH(E$8,$AD$8:$CF$8,0)),,,,-12)) -> 2737333.3 | F11: =+SUM(OFFSET(INDEX($AD11:$CF11,MATCH(F$8,$AD$8:$CF$8,0)),,,,-12)) -> 4066096.9 | G11: =+SUM(OFFSET(INDEX($AD11:$CL11,MATCH(G$8,$AD$8:$CL$8,0)),,,,-12)) -> 3975848.5 | I11: =SUMIFS($AD11:$BT11,$AD$5:$BT$5,I$5) -> 210700.16 | J11: =SUMIFS($AD11:$BT11,$AD$5:$BT$5,J$5) -> 200174.51 | K11: =SUMIFS($AD11:$BT11,$AD$5:$BT$5,K$5) -> 193928.72 | L11: =SUMIFS($AD11:$BT11,$AD$5:$BT$5,L$5) -> 176018.97 | M11: =SUMIFS($AD11:$BT11,$AD$5:$BT$5,M$5) -> 296323.49 | N11: =SUMIFS($AD11:$BT11,$AD$5:$BT$5,N$5) -> 381620.55 | O11: =SUMIFS($AD11:$BT11,$AD$5:$BT$5,O$5) -> 389129.23 | P11: =SUMIFS($AD11:$BT11,$AD$5:$BT$5,P$5) -> 564086.24 | ... V11: =SUMIFS($AD11:$BT11,$AD$5:$BT$5,V$5) -> 925202.28 | W11: =SUMIFS($AD11:$CF11,$AD$5:$CF$5,W$5) -> 1192998.1 | X11: =SUMIFS($AD11:$CF11,$AD$5:$CF$5,X$5) -> 1083652.9 | Y11: =SUMIFS($AD11:$CF11,$AD$5:$CF$5,Y$5) -> 803756.37 | Z11: =SUMIFS($AD11:$CF11,$AD$5:$CF$5,Z$5) -> 961801.53 | AA11: =SUMIFS($AD11:$CL11,$AD$5:$CL$5,AA$5) -> 931449.09 | AB11: =SUMIFS($AD11:$CL11,$AD$5:$CL$5,AB$5) -> 1278841.5 | AD11: ='Industrial ARR Rollforward'!AD11+'Fleet ARR Rollforward'!AD11 -> 26921.853 | AE11: ='Industrial ARR Rollforward'!AE11+'Fleet ARR Rollforward'!AE11 -> 97821.273 | AF11: ='Industrial ARR Rollforward'!AF11+'Fleet ARR Rollforward'!AF11 -> 85957.034 | AG11: ='Industrial ARR Rollforward'!AG11+'Fleet ARR Rollforward'!AG11 -> 62860.023 | AH11: ='Industrial ARR Rollforward'!AH11+'Fleet ARR Rollforward'!AH11 -> 40405.751 | AI11: ='Industrial ARR Rollforward'!AI11+'Fleet ARR Rollforward'!AI11 -> 96908.734 | AJ11: ='Industrial ARR Rollforward'!AJ11+'Fleet ARR Rollforward'!AJ11 -> 35556.547 | AK11: ='Industrial ARR Rollforward'!AK11+'Fleet ARR Rollforward'!AK11 -> 76030.99 | ... CK11: ='Industrial ARR Rollforward'!CK11+'Fleet ARR Rollforward'!CK11 -> 703733.61
B12: (-) Downsell | C12: =SUMIFS($I12:$W12,$I$7:$W$7,C$7) -> -1052015.6 | D12: =+SUM(OFFSET(INDEX($AD12:$CF12,MATCH(D$8,$AD$8:$CF$8,0)),,,,-12)) -> -1059599.2 | E12: =+SUM(OFFSET(INDEX($AD12:$CF12,MATCH(E$8,$AD$8:$CF$8,0)),,,,-12)) -> -1431568.4 | F12: =+SUM(OFFSET(INDEX($AD12:$CF12,MATCH(F$8,$AD$8:$CF$8,0)),,,,-12)) -> -1745938.1 | G12: =+SUM(OFFSET(INDEX($AD12:$CL12,MATCH(G$8,$AD$8:$CL$8,0)),,,,-12)) -> -2572102.5 | I12: =SUMIFS($AD12:$BT12,$AD$5:$BT$5,I$5) -> -166909.06 | J12: =SUMIFS($AD12:$BT12,$AD$5:$BT$5,J$5) -> -247648.93 | K12: =SUMIFS($AD12:$BT12,$AD$5:$BT$5,K$5) -> -279208.16 | L12: =SUMIFS($AD12:$BT12,$AD$5:$BT$5,L$5) -> -358249.43 | M12: =SUMIFS($AD12:$BT12,$AD$5:$BT$5,M$5) -> -232750.12 | N12: =SUMIFS($AD12:$BT12,$AD$5:$BT$5,N$5) -> -269313.16 | O12: =SUMIFS($AD12:$BT12,$AD$5:$BT$5,O$5) -> -248194.16 | P12: =SUMIFS($AD12:$BT12,$AD$5:$BT$5,P$5) -> -309341.75 | ... V12: =SUMIFS($AD12:$BT12,$AD$5:$BT$5,V$5) -> -419609.58 | W12: =SUMIFS($AD12:$CF12,$AD$5:$CF$5,W$5) -> -464105.56 | X12: =SUMIFS($AD12:$CF12,$AD$5:$CF$5,X$5) -> -532318.63 | Y12: =SUMIFS($AD12:$CF12,$AD$5:$CF$5,Y$5) -> -492783.28 | Z12: =SUMIFS($AD12:$CF12,$AD$5:$CF$5,Z$5) -> -832564.65 | AA12: =SUMIFS($AD12:$CL12,$AD$5:$CL$5,AA$5) -> -542240.37 | AB12: =SUMIFS($AD12:$CL12,$AD$5:$CL$5,AB$5) -> -704514.24 | AD12: ='Industrial ARR Rollforward'!AD12+'Fleet ARR Rollforward'!AD12 -> 0 | AE12: ='Industrial ARR Rollforward'!AE12+'Fleet ARR Rollforward'!AE12 -> -86653.692 | AF12: ='Industrial ARR Rollforward'!AF12+'Fleet ARR Rollforward'!AF12 -> -80255.371 | AG12: ='Industrial ARR Rollforward'!AG12+'Fleet ARR Rollforward'!AG12 -> -80670.171 | AH12: ='Industrial ARR Rollforward'!AH12+'Fleet ARR Rollforward'!AH12 -> -83158.802 | AI12: ='Industrial ARR Rollforward'!AI12+'Fleet ARR Rollforward'!AI12 -> -83819.955 | AJ12: ='Industrial ARR Rollforward'!AJ12+'Fleet ARR Rollforward'!AJ12 -> -94771.847 | AK12: ='Industrial ARR Rollforward'!AK12+'Fleet ARR Rollforward'!AK12 -> -79940.719 | ... CK12: ='Industrial ARR Rollforward'!CK12+'Fleet ARR Rollforward'!CK12 -> -219376.25
B13: (-) Churn | C13: =SUMIFS($I13:$W13,$I$7:$W$7,C$7) -> -336836.35 | D13: =+SUM(OFFSET(INDEX($AD13:$CF13,MATCH(D$8,$AD$8:$CF$8,0)),,,,-12)) -> -241267.98 | E13: =+SUM(OFFSET(INDEX($AD13:$CF13,MATCH(E$8,$AD$8:$CF$8,0)),,,,-12)) -> -153594 | F13: =+SUM(OFFSET(INDEX($AD13:$CF13,MATCH(F$8,$AD$8:$CF$8,0)),,,,-12)) -> -266851.46 | G13: =+SUM(OFFSET(INDEX($AD13:$CL13,MATCH(G$8,$AD$8:$CL$8,0)),,,,-12)) -> -431411.92 | I13: =SUMIFS($AD13:$BT13,$AD$5:$BT$5,I$5) -> -133279.02 | J13: =SUMIFS($AD13:$BT13,$AD$5:$BT$5,J$5) -> -97848.237 | K13: =SUMIFS($AD13:$BT13,$AD$5:$BT$5,K$5) -> -23393.674 | L13: =SUMIFS($AD13:$BT13,$AD$5:$BT$5,L$5) -> -82315.421 | M13: =SUMIFS($AD13:$BT13,$AD$5:$BT$5,M$5) -> -89643.649 | N13: =SUMIFS($AD13:$BT13,$AD$5:$BT$5,N$5) -> -34213.632 | O13: =SUMIFS($AD13:$BT13,$AD$5:$BT$5,O$5) -> -68111.496 | P13: =SUMIFS($AD13:$BT13,$AD$5:$BT$5,P$5) -> -49299.206 | ... V13: =SUMIFS($AD13:$BT13,$AD$5:$BT$5,V$5) -> -81980.833 | W13: =SUMIFS($AD13:$CF13,$AD$5:$CF$5,W$5) -> -62722.562 | X13: =SUMIFS($AD13:$CF13,$AD$5:$CF$5,X$5) -> -68212.4 | Y13: =SUMIFS($AD13:$CF13,$AD$5:$CF$5,Y$5) -> -67179.706 | Z13: =SUMIFS($AD13:$CF13,$AD$5:$CF$5,Z$5) -> -108443.86 | AA13: =SUMIFS($AD13:$CL13,$AD$5:$CL$5,AA$5) -> -126511.48 | AB13: =SUMIFS($AD13:$CL13,$AD$5:$CL$5,AB$5) -> -129276.86 | AD13: ='Industrial ARR Rollforward'!AD13+'Fleet ARR Rollforward'!AD13 -> 0 | AE13: ='Industrial ARR Rollforward'!AE13+'Fleet ARR Rollforward'!AE13 -> -59275.933 | AF13: ='Industrial ARR Rollforward'!AF13+'Fleet ARR Rollforward'!AF13 -> -74003.086 | AG13: ='Industrial ARR Rollforward'!AG13+'Fleet ARR Rollforward'!AG13 -> -21446.843 | AH13: ='Industrial ARR Rollforward'!AH13+'Fleet ARR Rollforward'!AH13 -> -24553.26 | AI13: ='Industrial ARR Rollforward'!AI13+'Fleet ARR Rollforward'!AI13 -> -51848.134 | AJ13: ='Industrial ARR Rollforward'!AJ13+'Fleet ARR Rollforward'!AJ13 -> -29631.607 | AK13: ='Industrial ARR Rollforward'!AK13+'Fleet ARR Rollforward'!AK13 -> 25632.697 | ... CK13: ='Industrial ARR Rollforward'!CK13+'Fleet ARR Rollforward'!CK13 -> -65234.183
B14: Ending ARR | C14: =SUM(C9:C13) -> 3507271 | D14: =SUM(D9:D13) -> 5002928.5 | E14: =SUM(E9:E13) -> 8109284.5 | F14: =SUM(F9:F13) -> 12126892 | G14: =SUM(G9:G13) -> 16656622 | I14: =SUM(I9:I13) -> 3495929.7 | J14: =SUM(J9:J13) -> 3452428.7 | K14: =SUM(K9:K13) -> 3577856.3 | L14: =SUM(L9:L13) -> 3507271 | M14: =SUM(M9:M13) -> 3631952.4 | N14: =SUM(N9:N13) -> 4203281.2 | O14: =SUM(O9:O13) -> 4549342.6 | P14: =SUM(P9:P13) -> 5002928.5 | ... AB14: =SUM(AB9:AB13) -> 16656622 | AD14: =SUM(AD9:AD13) -> 3529580 | AE14: =SUM(AE9:AE13) -> 3528617.5 | AF14: =SUM(AF9:AF13) -> 3495929.7 | AG14: =SUM(AG9:AG13) -> 3493397.3 | AH14: =SUM(AH9:AH13) -> 3449599.5 | AI14: =SUM(AI9:AI13) -> 3452428.7 | AJ14: =SUM(AJ9:AJ13) -> 3405075 | AK14: =SUM(AK9:AK13) -> 3496597.2 | ... CK14: =SUM(CK9:CK13) -> 16656622
B15: % YoY Growth | D15: =D14/C14-1 -> 0.4264448 | E15: =E14/D14-1 -> 0.62090752 | F15: =F14/E14-1 -> 0.49543303 | G15: =G14/G9-1 -> 0.37352774 | M15: =M14/I14-1 -> 0.038908854 | N15: =N14/J14-1 -> 0.2174853 | O15: =O14/K14-1 -> 0.27152747 | P15: =P14/L14-1 -> 0.4264448 | Q15: =Q14/M14-1 -> 0.47648599 | R15: =R14/N14-1 -> 0.43537867 | S15: =S14/O14-1 -> 0.57533454 | T15: =T14/P14-1 -> 0.62090752 | ... AB15: =AB14/X14-1 -> 0.37352774 | AP15: =AP14/AD14-1 -> -0.0060375599 | AQ15: =AQ14/AE14-1 -> 0.0016579198 | AR15: =AR14/AF14-1 -> 0.038908854 | AS15: =AS14/AG14-1 -> 0.093750555 | AT15: =AT14/AH14-1 -> 0.1731266 | AU15: =AU14/AI14-1 -> 0.2174853 | AV15: =AV14/AJ14-1 -> 0.27888057 | AW15: =AW14/AK14-1 -> 0.25071161 | ... CK15: =CK14/BY14-1 -> 0.37352774
B17: Gross Retention (c only) | D17: =1+D13/D9 -> 0.9312092 | E17: =1+E13/E9 -> 0.96929918 | F17: =1+F13/F9 -> 0.96709309 | G17: =1+G13/G9 -> 0.96442519 | J17: =1+J13*4/J9 -> 0.88804325 | K17: =1+K13*4/K9 -> 0.97289598 | L17: =1+L13*4/L9 -> 0.90797236 | M17: =1+M13*4/M9 -> 0.89776251 | N17: =1+N13*4/N9 -> 0.96231929 | O17: =1+O13*4/O9 -> 0.93518255 | P17: =1+P13*4/P9 -> 0.95665378 | Q17: =1+Q13*4/Q9 -> 0.99036981 | ... AB17: =1+AB13*4/AB9 -> 0.96614283 | AE17: =1+AE13*12/AE9 -> 0.79847144 | AF17: =1+AF13*12/AF9 -> 0.74833287 | AG17: =1+AG13*12/AG9 -> 0.92638235 | AH17: =1+AH13*12/AH9 -> 0.91565828 | AI17: =1+AI13*12/AI9 -> 0.81963773 | AJ17: =1+AJ13*12/AJ9 -> 0.89700605 | AK17: =1+AK13*12/AK9 -> 1.0903335 | AL17: =1+AL13*12/AL9 -> 0.93343895 | ... CK17: =1+CK13*12/CK9 -> 0.94987468
B18: Gross Retention (c + d) | D18: =1+SUM(D12:D13)/D9 -> 0.6290942 | E18: =1+SUM(E12:E13)/E9 -> 0.68315311 | F18: =1+SUM(F12:F13)/F9 -> 0.75179196 | G18: =1+SUM(G12:G13)/G9 -> 0.75232611 | J18: =1+SUM(J12:J13)*4/J9 -> 0.60468638 | K18: =1+SUM(K12:K13)*4/K9 -> 0.64940411 | L18: =1+SUM(L12:L13)*4/L9 -> 0.50745384 | M18: =1+SUM(M12:M13)*4/M9 -> 0.63231383 | N18: =1+SUM(N12:N13)*4/N9 -> 0.665715 | O18: =1+SUM(O12:O13)*4/O9 -> 0.69899168 | P18: =1+SUM(P12:P13)*4/P9 -> 0.68466568 | Q18: =1+SUM(Q12:Q13)*4/Q9 -> 0.68589102 | ... AB18: =1+SUM(AB12:AB13)*4/AB9 -> 0.78163297 | AE18: =1+SUM(AE12:AE13)*12/AE9 -> 0.50386293 | AF18: =1+SUM(AF12:AF13)*12/AF9 -> 0.47540318 | AG18: =1+SUM(AG12:AG13)*12/AG9 -> 0.64947689 | AH18: =1+SUM(AH12:AH13)*12/AH9 -> 0.63000351 | AI18: =1+SUM(AI12:AI13)*12/AI9 -> 0.52805621 | AJ18: =1+SUM(AJ12:AJ13)*12/AJ9 -> 0.56759674 | AK18: =1+SUM(AK12:AK13)*12/AK9 -> 0.80861031 | AL18: =1+SUM(AL12:AL13)*12/AL9 -> 0.57481968 | ... CK18: =1+SUM(CK12:CK13)*12/CK9 -> 0.78130806
B19: Net Retention | D19: =1+SUM(D11:D13)/D9 -> 1.0941736 | E19: =1+SUM(E11:E13)/E9 -> 1.2302993 | F19: =1+SUM(F11:F13)/F9 -> 1.2532045 | G19: =1+SUM(G11:G13)/G9 -> 1.08018 | J19: =1+SUM(J11:J13)*4/J9 -> 0.8337236 | K19: =1+SUM(K11:K13)*4/K9 -> 0.87409083 | L19: =1+SUM(L11:L13)*4/L9 -> 0.70424091 | M19: =1+SUM(M11:M13)*4/M9 -> 0.97026717 | N19: =1+SUM(N11:N13)*4/N9 -> 1.0860075 | O19: =1+SUM(O11:O13)*4/O9 -> 1.0693016 | P19: =1+SUM(P11:P13)*4/P9 -> 1.1806373 | Q19: =1+SUM(Q11:Q13)*4/Q9 -> 1.0127338 | ... AB19: =1+SUM(AB11:AB13)*4/AB9 -> 1.1165572 | AE19: =1+SUM(AE11:AE13)*12/AE9 -> 0.8364394 | AF19: =1+SUM(AF11:AF13)*12/AF9 -> 0.76772289 | AG19: =1+SUM(AG11:AG13)*12/AG9 -> 0.8652479 | AH19: =1+SUM(AH11:AH13)*12/AH9 -> 0.76879935 | AI19: =1+SUM(AI11:AI13)*12/AI9 -> 0.8651692 | AJ19: =1+SUM(AJ11:AJ13)*12/AJ9 -> 0.69118468 | AK19: =1+SUM(AK11:AK13)*12/AK9 -> 1.076555 | AL19: =1+SUM(AL11:AL13)*12/AL9 -> 0.85740706 | ... CK19: =1+SUM(CK11:CK13)*12/CK9 -> 1.3220502
B21: Net New ARR | C21: =SUM(C10:C13) -> 2792132.1 | D21: =SUM(D10:D13) -> 1495657.5 | E21: =SUM(E10:E13) -> 3106355.9 | F21: =SUM(F10:F13) -> 4017607.4 | G21: =SUM(G10:G13) -> 4529730.5 | I21: =SUM(I10:I13) -> 2780790.8 | J21: =SUM(J10:J13) -> -43501.015 | K21: =SUM(K10:K13) -> 125427.56 | L21: =SUM(L10:L13) -> -70585.261 | M21: =SUM(M10:M13) -> 124681.33 | N21: =SUM(N10:N13) -> 571328.85 | O21: =SUM(O10:O13) -> 346061.35 | P21: =SUM(P10:P13) -> 453585.96 | ... AB21: =SUM(AB10:AB13) -> 1383417.4 | AD21: =SUM(AD10:AD13) -> 2814441.1 | AE21: =SUM(AE10:AE13) -> -962.54568 | AF21: =SUM(AF10:AF13) -> -32687.728 | AG21: =SUM(AG10:AG13) -> -2532.4328 | AH21: =SUM(AH10:AH13) -> -43797.828 | AI21: =SUM(AI10:AI13) -> 2829.2464 | AJ21: =SUM(AJ10:AJ13) -> -47353.713 | AK21: =SUM(AK10:AK13) -> 91522.205 | ... CK21: =SUM(CK10:CK13) -> 1039561.8
B22: New + Upsell | C22: =SUM(C10:C11) -> 4180984 | D22: =SUM(D10:D11) -> 2796524.7 | E22: =SUM(E10:E11) -> 4691518.3 | F22: =SUM(F10:F11) -> 6030396.9 | G22: =SUM(G10:G11) -> 7533244.9 | I22: =SUM(I10:I11) -> 3080978.9 | J22: =SUM(J10:J11) -> 301996.15 | K22: =SUM(K10:K11) -> 428029.4 | L22: =SUM(L10:L11) -> 369979.59 | M22: =SUM(M10:M11) -> 447075.1 | N22: =SUM(N10:N11) -> 874855.65 | O22: =SUM(O10:O11) -> 662367.01 | P22: =SUM(P10:P11) -> 812226.92 | ... AB22: =SUM(AB10:AB11) -> 2217208.5 | AD22: =SUM(AD10:AD11) -> 2814441.1 | AE22: =SUM(AE10:AE11) -> 144967.08 | AF22: =SUM(AF10:AF11) -> 121570.73 | AG22: =SUM(AG10:AG11) -> 99584.581 | AH22: =SUM(AH10:AH11) -> 63914.233 | AI22: =SUM(AI10:AI11) -> 138497.34 | AJ22: =SUM(AJ10:AJ11) -> 77049.741 | AK22: =SUM(AK10:AK11) -> 145830.23 | ... CK22: =SUM(CK10:CK11) -> 1324172.2
B24: Customer Count
B25: Beginning Logos | C25: =I25 -> 25 | D25: =C28 -> 9604 | E25: =D28 -> 10605 | F25: =E28 -> 11462 | G25: =+SUMIFS($AD$28:$CL$28,$AD$8:$CL$8,EOMONTH(G8,-12)) -> 12072 | I25: =AD25 -> 25 | J25: =I28 -> 8903 | K25: =J28 -> 8977 | L25: =K28 -> 9254 | M25: =L28 -> 9604 | N25: =M28 -> 9825 | O25: =N28 -> 10242 | P25: =O28 -> 10420 | Q25: =P28 -> 10605 | ... AB25: =AA28 -> 12217 | AD25: ='Industrial ARR Rollforward'!AD25+'Fleet ARR Rollforward'!AD25 -> 25 | AE25: ='Industrial ARR Rollforward'!AE25+'Fleet ARR Rollforward'!AE25 -> 8886 | AF25: ='Industrial ARR Rollforward'!AF25+'Fleet ARR Rollforward'!AF25 -> 8876 | AG25: ='Industrial ARR Rollforward'!AG25+'Fleet ARR Rollforward'!AG25 -> 8903 | AH25: ='Industrial ARR Rollforward'!AH25+'Fleet ARR Rollforward'!AH25 -> 8913 | AI25: ='Industrial ARR Rollforward'!AI25+'Fleet ARR Rollforward'!AI25 -> 8897 | AJ25: ='Industrial ARR Rollforward'!AJ25+'Fleet ARR Rollforward'!AJ25 -> 8977 | AK25: ='Industrial ARR Rollforward'!AK25+'Fleet ARR Rollforward'!AK25 -> 8978 | ... CK25: ='Industrial ARR Rollforward'!CK25+'Fleet ARR Rollforward'!CK25 -> 12206
B26: (+) New | C26: =SUMIFS($I26:$W26,$I$7:$W$7,C$7) -> 11058 | D26: =SUMIFS($I26:$W26,$I$7:$W$7,D$7) -> 2296 | E26: =SUMIFS($I26:$W26,$I$7:$W$7,E$7) -> 2230 | F26: =SUMIFS($I26:$AC26,$I$7:$AC$7,F$7) -> 2898 | G26: =+SUM(OFFSET(INDEX($AD26:$CL26,MATCH(G$8,$AD$8:$CL$8,0)),,,,-12)) -> 3156 | I26: =SUMIFS($AD26:$BT26,$AD$5:$BT$5,I$5) -> 9184 | J26: =SUMIFS($AD26:$BT26,$AD$5:$BT$5,J$5) -> 446 | K26: =SUMIFS($AD26:$BT26,$AD$5:$BT$5,K$5) -> 696 | L26: =SUMIFS($AD26:$BT26,$AD$5:$BT$5,L$5) -> 732 | M26: =SUMIFS($AD26:$BT26,$AD$5:$BT$5,M$5) -> 559 | N26: =SUMIFS($AD26:$BT26,$AD$5:$BT$5,N$5) -> 666 | O26: =SUMIFS($AD26:$BT26,$AD$5:$BT$5,O$5) -> 550 | P26: =SUMIFS($AD26:$BT26,$AD$5:$BT$5,P$5) -> 521 | ... V26: =SUMIFS($AD26:$BT26,$AD$5:$BT$5,V$5) -> 680 | W26: =SUMIFS($AD26:$CF26,$AD$5:$CF$5,W$5) -> 703 | X26: =SUMIFS($AD26:$CF26,$AD$5:$CF$5,X$5) -> 799 | Y26: =SUMIFS($AD26:$CF26,$AD$5:$CF$5,Y$5) -> 689 | Z26: =SUMIFS($AD26:$CF26,$AD$5:$CF$5,Z$5) -> 744 | AA26: =SUMIFS($AD26:$CL26,$AD$5:$CL$5,AA$5) -> 838 | AB26: =SUMIFS($AD26:$CL26,$AD$5:$CL$5,AB$5) -> 885 | AD26: ='Industrial ARR Rollforward'!AD26+'Fleet ARR Rollforward'!AD26 -> 8861 | AE26: ='Industrial ARR Rollforward'!AE26+'Fleet ARR Rollforward'!AE26 -> 152 | AF26: ='Industrial ARR Rollforward'!AF26+'Fleet ARR Rollforward'!AF26 -> 171 | AG26: ='Industrial ARR Rollforward'!AG26+'Fleet ARR Rollforward'!AG26 -> 146 | AH26: ='Industrial ARR Rollforward'!AH26+'Fleet ARR Rollforward'!AH26 -> 103 | AI26: ='Industrial ARR Rollforward'!AI26+'Fleet ARR Rollforward'!AI26 -> 197 | AJ26: ='Industrial ARR Rollforward'!AJ26+'Fleet ARR Rollforward'!AJ26 -> 166 | AK26: ='Industrial ARR Rollforward'!AK26+'Fleet ARR Rollforward'!AK26 -> 222 | ... CK26: ='Industrial ARR Rollforward'!CK26+'Fleet ARR Rollforward'!CK26 -> 294
B27: (-) Cancel | C27: =SUMIFS($I27:$W27,$I$7:$W$7,C$7) -> -1479 | D27: =SUMIFS($I27:$W27,$I$7:$W$7,D$7) -> -1295 | E27: =SUMIFS($I27:$W27,$I$7:$W$7,E$7) -> -1373 | F27: =SUMIFS($I27:$AC27,$I$7:$AC$7,F$7) -> -2288 | G27: =+SUM(OFFSET(INDEX($AD27:$CL27,MATCH(G$8,$AD$8:$CL$8,0)),,,,-12)) -> -3021 | I27: =SUMIFS($AD27:$BT27,$AD$5:$BT$5,I$5) -> -306 | J27: =SUMIFS($AD27:$BT27,$AD$5:$BT$5,J$5) -> -372 | K27: =SUMIFS($AD27:$BT27,$AD$5:$BT$5,K$5) -> -419 | L27: =SUMIFS($AD27:$BT27,$AD$5:$BT$5,L$5) -> -382 | M27: =SUMIFS($AD27:$BT27,$AD$5:$BT$5,M$5) -> -338 | N27: =SUMIFS($AD27:$BT27,$AD$5:$BT$5,N$5) -> -249 | O27: =SUMIFS($AD27:$BT27,$AD$5:$BT$5,O$5) -> -372 | P27: =SUMIFS($AD27:$BT27,$AD$5:$BT$5,P$5) -> -336 | ... V27: =SUMIFS($AD27:$BT27,$AD$5:$BT$5,V$5) -> -460 | W27: =SUMIFS($AD27:$CF27,$AD$5:$CF$5,W$5) -> -648 | X27: =SUMIFS($AD27:$CF27,$AD$5:$CF$5,X$5) -> -797 | Y27: =SUMIFS($AD27:$CF27,$AD$5:$CF$5,Y$5) -> -723 | Z27: =SUMIFS($AD27:$CF27,$AD$5:$CF$5,Z$5) -> -642 | AA27: =SUMIFS($AD27:$CL27,$AD$5:$CL$5,AA$5) -> -761 | AB27: =SUMIFS($AD27:$CL27,$AD$5:$CL$5,AB$5) -> -895 | AD27: ='Industrial ARR Rollforward'!AD27+'Fleet ARR Rollforward'!AD27 -> 0 | AE27: ='Industrial ARR Rollforward'!AE27+'Fleet ARR Rollforward'!AE27 -> -162 | AF27: ='Industrial ARR Rollforward'!AF27+'Fleet ARR Rollforward'!AF27 -> -144 | AG27: ='Industrial ARR Rollforward'!AG27+'Fleet ARR Rollforward'!AG27 -> -136 | AH27: ='Industrial ARR Rollforward'!AH27+'Fleet ARR Rollforward'!AH27 -> -119 | AI27: ='Industrial ARR Rollforward'!AI27+'Fleet ARR Rollforward'!AI27 -> -117 | AJ27: ='Industrial ARR Rollforward'!AJ27+'Fleet ARR Rollforward'!AJ27 -> -165 | AK27: ='Industrial ARR Rollforward'!AK27+'Fleet ARR Rollforward'!AK27 -> -121 | ... CK27: ='Industrial ARR Rollforward'!CK27+'Fleet ARR Rollforward'!CK27 -> -293
B28: Ending Logos | C28: =SUM(C25:C27) -> 9604 | D28: =SUM(D25:D27) -> 10605 | E28: =SUM(E25:E27) -> 11462 | F28: =SUM(F25:F27) -> 12072 | G28: =SUM(G25:G27) -> 12207 | I28: =SUM(I25:I27) -> 8903 | J28: =SUM(J25:J27) -> 8977 | K28: =SUM(K25:K27) -> 9254 | L28: =SUM(L25:L27) -> 9604 | M28: =SUM(M25:M27) -> 9825 | N28: =SUM(N25:N27) -> 10242 | O28: =SUM(O25:O27) -> 10420 | P28: =SUM(P25:P27) -> 10605 | ... AB28: =SUM(AB25:AB27) -> 12207 | AD28: =SUM(AD25:AD27) -> 8886 | AE28: =SUM(AE25:AE27) -> 8876 | AF28: =SUM(AF25:AF27) -> 8903 | AG28: =SUM(AG25:AG27) -> 8913 | AH28: =SUM(AH25:AH27) -> 8897 | AI28: =SUM(AI25:AI27) -> 8977 | AJ28: =SUM(AJ25:AJ27) -> 8978 | AK28: =SUM(AK25:AK27) -> 9079 | ... CK28: =SUM(CK25:CK27) -> 12207
B30: Logo Retention | C30: =1+C27/C28 -> 0.84600167 | D30: =1+D27/D28 -> 0.87788779 | E30: =1+E27/E28 -> 0.88021288 | F30: =1+F27/F28 -> 0.81047051 | G30: =1+G27/G28 -> 0.75251905 | J30: =1+J27*4/J25 -> 0.83286533 | K30: =1+K27*4/K25 -> 0.81330066 | L30: =1+L27*4/L25 -> 0.83488221 | M30: =1+M27*4/M25 -> 0.85922532 | N30: =1+N27*4/N25 -> 0.89862595 | O30: =1+O27*4/O25 -> 0.85471588 | P30: =1+P27*4/P25 -> 0.87101727 | Q30: =1+Q27*4/Q25 -> 0.87854785 | ... AB30: =1+AB27*4/AB25 -> 0.7069657 | AE30: =1+AE27*12/AE25 -> 0.7812289 | AF30: =1+AF27*12/AF25 -> 0.80531771 | AG30: =1+AG27*12/AG25 -> 0.816691 | AH30: =1+AH27*12/AH25 -> 0.83978458 | AI30: =1+AI27*12/AI25 -> 0.842194 | AJ30: =1+AJ27*12/AJ25 -> 0.77943634 | AK30: =1+AK27*12/AK25 -> 0.83827133 | AL30: =1+AL27*12/AL25 -> 0.82420971 | ... CK30: =1+CK27*12/CK25 -> 0.71194495
B32: Avg. ARR / Cust | C32: =C14/C28 -> 365.18857 | D32: =D14/D28 -> 471.75187 | E32: =E14/E28 -> 707.49297 | F32: =F14/F28 -> 1004.547 | G32: =G14/G28 -> 1364.514 | I32: =I14/I28 -> 392.66873 | J32: =J14/J28 -> 384.58602 | K32: =K14/K28 -> 386.62808 | L32: =L14/L28 -> 365.18857 | M32: =M14/M28 -> 369.66436 | N32: =N14/N28 -> 410.39653 | O32: =O14/O28 -> 436.59718 | P32: =P14/P28 -> 471.75187 | ... AB32: =AB14/AB28 -> 1364.514 | AE32: =AE14/AE28 -> 397.54591 | AF32: =AF14/AF28 -> 392.66873 | AG32: =AG14/AG28 -> 391.94405 | AH32: =AH14/AH28 -> 387.72614 | AI32: =AI14/AI28 -> 384.58602 | AJ32: =AJ14/AJ28 -> 379.26877 | AK32: =AK14/AK28 -> 385.13022 | AL32: =AL14/AL28 -> 386.62808 | ... CK32: =CK14/CK28 -> 1364.514
B33: Avg. ARR / New | C33: =C10/C26 -> 307.48433 | D33: =D10/D26 -> 507.56323 | E33: =E10/E26 -> 876.31614 | F33: =F10/F26 -> 677.81231 | G33: =G10/G26 -> 1127.1852 | I33: =I10/I26 -> 312.53035 | J33: =J10/J26 -> 228.29965 | K33: =K10/K26 -> 336.35154 | L33: =L10/L26 -> 264.97353 | M33: =M10/M26 -> 269.68088 | N33: =N10/N26 -> 740.59324 | O33: =O10/O26 -> 496.79596 | P33: =P10/P26 -> 476.2777 | ... AB33: =AB10/AB26 -> 1060.3017 | AE33: =AE10/AE26 -> 310.16978 | AF33: =AF10/AF26 -> 208.26723 | AG33: =AG10/AG26 -> 251.53807 | AH33: =AH10/AH26 -> 228.23769 | AI33: =AI10/AI26 -> 211.10965 | AJ33: =AJ10/AJ26 -> 249.959 | AK33: =AK10/AK26 -> 314.41098 | AL33: =AL10/AL26 -> 398.72807 | ... CK33: =CK10/CK26 -> 2110.3353
B34: Avg. ARR / Churn | C34: =IFERROR(C13/C27,"NA") -> 227.74601 | D34: =IFERROR(D13/D27,"NA") -> 186.30732 | E34: =IFERROR(E13/E27,"NA") -> 111.86745 | F34: =IFERROR(F13/F27,"NA") -> 116.63088 | G34: =IFERROR(G13/G27,"NA") -> 142.80434 | I34: =IFERROR(I13/I27,"NA") -> 435.55235 | J34: =IFERROR(J13/J27,"NA") -> 263.03289 | K34: =IFERROR(K13/K27,"NA") -> 55.832157 | L34: =IFERROR(L13/L27,"NA") -> 215.48539 | M34: =IFERROR(M13/M27,"NA") -> 265.2179 | N34: =IFERROR(N13/N27,"NA") -> 137.40415 | O34: =IFERROR(O13/O27,"NA") -> 183.09542 | P34: =IFERROR(P13/P27,"NA") -> 146.72383 | ... AB34: =IFERROR(AB13/AB27,"NA") -> 144.44342 | AE34: =IFERROR(AE13/AE27,"NA") -> 365.90082 | AF34: =IFERROR(AF13/AF27,"NA") -> 513.91032 | AG34: =IFERROR(AG13/AG27,"NA") -> 157.69738 | AH34: =IFERROR(AH13/AH27,"NA") -> 206.32992 | AI34: =IFERROR(AI13/AI27,"NA") -> 443.14644 | AJ34: =IFERROR(AJ13/AJ27,"NA") -> 179.58549 | AK34: =IFERROR(AK13/AK27,"NA") -> -211.84047 | AL34: =IFERROR(AL13/AL27,"NA") -> 145.82529 | ... CK34: =IFERROR(CK13/CK27,"NA") -> 222.64226
C36: =C37&" " &YEAR(C39) -> Q4 2021 | D36: =D37&" " &YEAR(D39) -> Q4 2022 | E36: =E37&" " &YEAR(E39) -> Q4 2023 | F36: =F37&" " &YEAR(F39) -> Q4 2024 | G36: =G37&" " &YEAR(G39) -> TTM 2025 | I36: =I37&" " &YEAR(I39) -> Q1 2021 | J36: =J37&" " &YEAR(J39) -> Q2 2021 | K36: =K37&" " &YEAR(K39) -> Q3 2021 | L36: =L37&" " &YEAR(L39) -> Q4 2021 | M36: =M37&" " &YEAR(M39) -> Q1 2022 | N36: =N37&" " &YEAR(N39) -> Q2 2022 | O36: =O37&" " &YEAR(O39) -> Q3 2022 | P36: =P37&" " &YEAR(P39) -> Q4 2022 | ... AB36: =AB37&" " &YEAR(AB39) -> Q4 2025 | AD36: =AD37&" " &YEAR(AD39) -> Q1 2021 | AE36: =AE37&" " &YEAR(AE39) -> Q1 2021 | AF36: =AF37&" " &YEAR(AF39) -> Q1 2021 | AG36: =AG37&" " &YEAR(AG39) -> Q2 2021 | AH36: =AH37&" " &YEAR(AH39) -> Q2 2021 | AI36: =AI37&" " &YEAR(AI39) -> Q2 2021 | AJ36: =AJ37&" " &YEAR(AJ39) -> Q3 2021 | AK36: =AK37&" " &YEAR(AK39) -> Q3 2021 | ... CK36: =CK37&" " &YEAR(CK39) -> Q4 2025
C37: Q4 | D37: Q4 | E37: Q4 | F37: Q4 | G37: TTM | I37: =+I6 -> Q1 | J37: =+J6 -> Q2 | K37: =+K6 -> Q3 | L37: =+L6 -> Q4 | M37: =+M6 -> Q1 | N37: =+N6 -> Q2 | O37: =+O6 -> Q3 | P37: =+P6 -> Q4 | ... AB37: =+AB6 -> Q4 | AD37: =+AD6 -> Q1 | AE37: =+AE6 -> Q1 | AF37: =+AF6 -> Q1 | AG37: =+AG6 -> Q2 | AH37: =+AH6 -> Q2 | AI37: =+AI6 -> Q2 | AJ37: =+AJ6 -> Q3 | AK37: =+AK6 -> Q3 | ... CK37: =+CK6 -> Q4
C38: =YEAR(C39) -> 2021 | D38: =YEAR(D39) -> 2022 | E38: =YEAR(E39) -> 2023 | F38: =YEAR(F39) -> 2024 | G38: =YEAR(G39) -> 2025 | I38: =+I7 -> 2021 | J38: =+J7 -> 2021 | K38: =+K7 -> 2021 | L38: =+L7 -> 2021 | M38: =+M7 -> 2022 | N38: =+N7 -> 2022 | O38: =+O7 -> 2022 | P38: =+P7 -> 2022 | ... AB38: =+AB7 -> 2025 | AD38: =+AD7 -> 2021 | AE38: =+AE7 -> 2021 | AF38: =+AF7 -> 2021 | AG38: =+AG7 -> 2021 | AH38: =+AH7 -> 2021 | AI38: =+AI7 -> 2021 | AJ38: =+AJ7 -> 2021 | AK38: =+AK7 -> 2021 | ... CK38: =+CK7 -> 2025
B39: Consolidated Sales Efficiency | C39: =+C8 -> 44561 | D39: =+D8 -> 44926 | E39: =+E8 -> 45291 | F39: =+F8 -> 45657 | G39: =+G8 -> 46022 | I39: =+I8 -> 44286 | J39: =+J8 -> 44377 | K39: =+K8 -> 44469 | L39: =+L8 -> 44561 | M39: =+M8 -> 44651 | N39: =+N8 -> 44742 | O39: =+O8 -> 44834 | P39: =+P8 -> 44926 | ... AB39: =+AB8 -> 46022 | AD39: =+AD8 -> 44227 | AE39: =+AE8 -> 44255 | AF39: =+AF8 -> 44286 | AG39: =+AG8 -> 44316 | AH39: =+AH8 -> 44347 | AI39: =+AI8 -> 44377 | AJ39: =+AJ8 -> 44408 | AK39: =+AK8 -> 44439 | ... CK39: =+CK8 -> 46022
B41: Customer Lifetime Value
B42: New + Upsell | C42: =SUM(C10:C11) -> 4180984 | D42: =SUM(D10:D11) -> 2796524.7 | E42: =SUM(E10:E11) -> 4691518.3 | F42: =SUM(F10:F11) -> 6030396.9 | G42: =SUM(G10:G11) -> 7533244.9 | I42: =SUM(I10:I11) -> 3080978.9 | J42: =SUM(J10:J11) -> 301996.15 | K42: =SUM(K10:K11) -> 428029.4 | L42: =SUM(L10:L11) -> 369979.59 | M42: =SUM(M10:M11) -> 447075.1 | N42: =SUM(N10:N11) -> 874855.65 | O42: =SUM(O10:O11) -> 662367.01 | P42: =SUM(P10:P11) -> 812226.92 | ... AB42: =SUM(AB10:AB11) -> 2217208.5 | AD42: =SUM(AD10:AD11) -> 2814441.1 | AE42: =SUM(AE10:AE11) -> 144967.08 | AF42: =SUM(AF10:AF11) -> 121570.73 | AG42: =SUM(AG10:AG11) -> 99584.581 | AH42: =SUM(AH10:AH11) -> 63914.233 | AI42: =SUM(AI10:AI11) -> 138497.34 | AJ42: =SUM(AJ10:AJ11) -> 77049.741 | AK42: =SUM(AK10:AK11) -> 145830.23 | ... CK42: =SUM(CK10:CK11) -> 1324172.2
B43: Gross Margin | C43: 0.7049489 | D43: =+'Industrial ARR Rollforward'!D43 -> 0.72510895 | E43: =+'Industrial ARR Rollforward'!E43 -> 0.75651534 | F43: =+'Industrial ARR Rollforward'!F43 -> 0.77942405 | G43: =+'Industrial ARR Rollforward'!G43 -> 0.75533729 | I43: =AVERAGEIFS($AD43:$BT43,$AD$36:$BT$36,I$36) -> 0.70331208 | J43: =AVERAGEIFS($AD43:$BT43,$AD$36:$BT$36,J$36) -> 0.75287296 | K43: =AVERAGEIFS($AD43:$BT43,$AD$36:$BT$36,K$36) -> 0.73170588 | L43: =AVERAGEIFS($AD43:$BT43,$AD$36:$BT$36,L$36) -> 0.76169227 | M43: =AVERAGEIFS($AD43:$BT43,$AD$36:$BT$36,M$36) -> 0.72432258 | N43: =AVERAGEIFS($AD43:$BT43,$AD$36:$BT$36,N$36) -> 0.70519993 | O43: =AVERAGEIFS($AD43:$BT43,$AD$36:$BT$36,O$36) -> 0.72702076 | P43: =AVERAGEIFS($AD43:$BT43,$AD$36:$BT$36,P$36) -> 0.73995139 | ... V43: =AVERAGEIFS($AD43:$BT43,$AD$36:$BT$36,V$36) -> 0.78066093 | W43: =AVERAGEIFS($AD43:$CF43,$AD$36:$CF$36,W$36) -> 0.77526965 | X43: =AVERAGEIFS($AD43:$CF43,$AD$36:$CF$36,X$36) -> 0.78768385 | Y43: =AVERAGEIFS($AD43:$CF43,$AD$36:$CF$36,Y$36) -> 0.76892265 | Z43: =AVERAGEIFS($AD43:$CF43,$AD$36:$CF$36,Z$36) -> 0.75446338 | AA43: =AVERAGEIFS($AD43:$CL43,$AD$36:$CL$36,AA$36) -> 0.75623831 | AB43: =AVERAGEIFS($AD43:$CL43,$AD$36:$CL$36,AB$36) -> 0.74171109 | AD43: =+'Cons TrioMobil | Monthly'!O24 -> 0.66228422 | AE43: =+'Cons TrioMobil | Monthly'!P24 -> 0.72075982 | AF43: =+'Cons TrioMobil | Monthly'!Q24 -> 0.72689219 | AG43: =+'Cons TrioMobil | Monthly'!R24 -> 0.78612543 | AH43: =+'Cons TrioMobil | Monthly'!S24 -> 0.74211799 | AI43: =+'Cons TrioMobil | Monthly'!T24 -> 0.73037545 | AJ43: =+'Cons TrioMobil | Monthly'!U24 -> 0.7471152 | AK43: =+'Cons TrioMobil | Monthly'!V24 -> 0.6971837 | ... CK43: =+'Cons TrioMobil | Monthly'!BV24 -> 0.72957513
B44: Gross Profit | C44: =C43*C42 -> 2947380.1 | D44: =D43*D42 -> 2027785.1 | E44: =E43*E42 -> 3549205.6 | F44: =F43*F42 -> 4700236.4 | G44: =G43*G42 -> 5690140.8 | I44: =I43*I42 -> 2166889.7 | J44: =J43*J42 -> 227364.73 | K44: =K43*K42 -> 313191.63 | L44: =L43*L42 -> 281810.59 | M44: =M43*M42 -> 323826.59 | N44: =N43*N42 -> 616948.15 | O44: =O43*O42 -> 481554.57 | P44: =P43*P42 -> 601008.44 | ... AB44: =AB43*AB42 -> 1644528.2 | AD44: =AD43*AD42 -> 1863959.9 | AE44: =AE43*AE42 -> 104486.45 | AF44: =AF43*AF42 -> 88368.814 | AG44: =AG43*AG42 -> 78285.972 | AH44: =AH43*AH42 -> 47431.902 | AI44: =AI43*AI42 -> 101155.05 | AJ44: =AJ43*AJ42 -> 57565.033 | AK44: =AK43*AK42 -> 101670.46 | ... CK44: =CK43*CK42 -> 966083.1
B46: Logo Retention | C46: =C30 -> 0.84600167 | D46: =D30 -> 0.87788779 | E46: =E30 -> 0.88021288 | F46: =F30 -> 0.81047051 | G46: =G30 -> 0.75251905 | J46: =J30 -> 0.83286533 | K46: =K30 -> 0.81330066 | L46: =L30 -> 0.83488221 | M46: =M30 -> 0.85922532 | N46: =N30 -> 0.89862595 | O46: =O30 -> 0.85471588 | P46: =P30 -> 0.87101727 | Q46: =Q30 -> 0.87854785 | ... AB46: =AB30 -> 0.7069657 | AE46: =AE30 -> 0.7812289 | AF46: =AF30 -> 0.80531771 | AG46: =AG30 -> 0.816691 | AH46: =AH30 -> 0.83978458 | AI46: =AI30 -> 0.842194 | AJ46: =AJ30 -> 0.77943634 | AK46: =AK30 -> 0.83827133 | AL46: =AL30 -> 0.82420971 | ... CK46: =CK30 -> 0.71194495
B47: Implied Customer Years (Calculated) | C47: =IF(C46=100%,100,IFERROR(1/(1-C46),"NA")) -> 6.4935767 | D47: =IF(D46=100%,100,IFERROR(1/(1-D46),"NA")) -> 8.1891892 | E47: =IF(E46=100%,100,IFERROR(1/(1-E46),"NA")) -> 8.3481428 | F47: =IF(F46=100%,100,IFERROR(1/(1-F46),"NA")) -> 5.2762238 | G47: =IF(G46=100%,100,IFERROR(1/(1-G46),"NA")) -> 4.040715 | J47: =IF(J46=100%,100,IFERROR(1/(1-J46),"NA")) -> 5.9831989 | K47: =IF(K46=100%,100,IFERROR(1/(1-K46),"NA")) -> 5.3562053 | L47: =IF(L46=100%,100,IFERROR(1/(1-L46),"NA")) -> 6.0562827 | M47: =IF(M46=100%,100,IFERROR(1/(1-M46),"NA")) -> 7.1035503 | N47: =IF(N46=100%,100,IFERROR(1/(1-N46),"NA")) -> 9.8644578 | O47: =IF(O46=100%,100,IFERROR(1/(1-O46),"NA")) -> 6.8830645 | P47: =IF(P46=100%,100,IFERROR(1/(1-P46),"NA")) -> 7.7529762 | Q47: =IF(Q46=100%,100,IFERROR(1/(1-Q46),"NA")) -> 8.2336957 | ... AB47: =IF(AB46=100%,100,IFERROR(1/(1-AB46),"NA")) -> 3.4125698 | AE47: =IF(AE46=100%,100,IFERROR(1/(1-AE46),"NA")) -> 4.5709877 | AF47: =IF(AF46=100%,100,IFERROR(1/(1-AF46),"NA")) -> 5.1365741 | AG47: =IF(AG46=100%,100,IFERROR(1/(1-AG46),"NA")) -> 5.4552696 | AH47: =IF(AH46=100%,100,IFERROR(1/(1-AH46),"NA")) -> 6.2415966 | AI47: =IF(AI46=100%,100,IFERROR(1/(1-AI46),"NA")) -> 6.3368946 | AJ47: =IF(AJ46=100%,100,IFERROR(1/(1-AJ46),"NA")) -> 4.5338384 | AK47: =IF(AK46=100%,100,IFERROR(1/(1-AK46),"NA")) -> 6.1831956 | AL47: =IF(AL46=100%,100,IFERROR(1/(1-AL46),"NA")) -> 5.6885965 | ... CK47: =IF(CK46=100%,100,IFERROR(1/(1-CK46),"NA")) -> 3.4715586
B48: Implied Customer Years (Capped) | C48: =MIN(C47,5) -> 5 | D48: =MIN(D47,5) -> 5 | E48: =MIN(E47,5) -> 5 | F48: =MIN(F47,5) -> 5 | G48: =MIN(G47,5) -> 4.040715 | J48: =MIN(J47,5) -> 5 | K48: =MIN(K47,5) -> 5 | L48: =MIN(L47,5) -> 5 | M48: =MIN(M47,5) -> 5 | N48: =MIN(N47,5) -> 5 | O48: =MIN(O47,5) -> 5 | P48: =MIN(P47,5) -> 5 | Q48: =MIN(Q47,5) -> 5 | ... AB48: =MIN(AB47,5) -> 3.4125698 | AE48: =MIN(AE47,5) -> 4.5709877 | AF48: =MIN(AF47,5) -> 5 | AG48: =MIN(AG47,5) -> 5 | AH48: =MIN(AH47,5) -> 5 | AI48: =MIN(AI47,5) -> 5 | AJ48: =MIN(AJ47,5) -> 4.5338384 | AK48: =MIN(AK47,5) -> 5 | AL48: =MIN(AL47,5) -> 5 | ... CK48: =MIN(CK47,5) -> 3.4715586
B49: CLTV | C49: =C48*C44 -> 14736901 | D49: =D48*D44 -> 10138925 | E49: =E48*E44 -> 17746028 | F49: =F48*F44 -> 23501182 | G49: =G48*G44 -> 22992237 | J49: =J48*J44 -> 1136823.7 | K49: =K48*K44 -> 1565958.1 | L49: =L48*L44 -> 1409053 | M49: =M48*M44 -> 1619132.9 | N49: =N48*N44 -> 3084740.7 | O49: =O48*O44 -> 2407772.8 | P49: =P48*P44 -> 3005042.2 | Q49: =Q48*Q44 -> 2777959 | ... AB49: =AB48*AB44 -> 5612067.2 | AE49: =AE48*AE44 -> 477606.26 | AF49: =AF48*AF44 -> 441844.07 | AG49: =AG48*AG44 -> 391429.86 | AH49: =AH48*AH44 -> 237159.51 | AI49: =AI48*AI44 -> 505775.27 | AJ49: =AJ48*AJ44 -> 260990.56 | AK49: =AK48*AK44 -> 508352.29 | AL49: =AL48*AL44 -> 770150.18 | ... CK49: =CK48*CK44 -> 3353814.1
B51: CAC % | C51: 1 | D51: 1 | E51: 1 | F51: 1 | G51: 1 | J51: =AVERAGEIFS($AD51:$BT51,$AD$36:$BT$36,J$36) -> 1 | K51: =AVERAGEIFS($AD51:$BT51,$AD$36:$BT$36,K$36) -> 1 | L51: =AVERAGEIFS($AD51:$BT51,$AD$36:$BT$36,L$36) -> 1 | M51: =AVERAGEIFS($AD51:$BT51,$AD$36:$BT$36,M$36) -> 1 | N51: =AVERAGEIFS($AD51:$BT51,$AD$36:$BT$36,N$36) -> 1 | O51: =AVERAGEIFS($AD51:$BT51,$AD$36:$BT$36,O$36) -> 1 | P51: =AVERAGEIFS($AD51:$BT51,$AD$36:$BT$36,P$36) -> 1 | Q51: =AVERAGEIFS($AD51:$BT51,$AD$36:$BT$36,Q$36) -> 1 | ... V51: =AVERAGEIFS($AD51:$BT51,$AD$36:$BT$36,V$36) -> 1 | W51: =AVERAGEIFS($AD51:$CF51,$AD$36:$CF$36,W$36) -> 1 | X51: =AVERAGEIFS($AD51:$CF51,$AD$36:$CF$36,X$36) -> 1 | Y51: =AVERAGEIFS($AD51:$CF51,$AD$36:$CF$36,Y$36) -> 1 | Z51: =AVERAGEIFS($AD51:$CF51,$AD$36:$CF$36,Z$36) -> 1 | AA51: =AVERAGEIFS($AD51:$CL51,$AD$36:$CL$36,AA$36) -> 1 | AB51: =AVERAGEIFS($AD51:$CL51,$AD$36:$CL$36,AB$36) -> 1 | AE51: 1 | AF51: 1 | AG51: 1 | AH51: 1 | AI51: 1 | AJ51: 1 | AK51: 1 | AL51: 1 | AM51: 1 | AN51: 1 | AO51: 1 | AP51: 1 | AQ51: 1 | AR51: 1 | AS51: 1 | AT51: 1 | AU51: 1 | AV51: 1 | AW51: 1 | AX51: 1 | AY51: 1 | AZ51: 1 | BA51: 1 | BB51: 1 | BC51: 1 | BD51: 1 | BE51: 1 | BF51: 1 | BG51: 1 | BH51: 1 | BI51: 1 | BJ51: 1 | BK51: 1 | BL51: 1 | BM51: 1 | BN51: 1 | BO51: 1 | BP51: 1 | BQ51: 1 | BR51: 1 | BS51: 1 | BT51: 1 | BU51: 1 | BV51: 1 | BW51: 1 | BX51: 1 | BY51: 1 | BZ51: 1 | CA51: 1 | CB51: 1 | CC51: 1 | CD51: 1 | CE51: 1 | CF51: 1 | CG51: 1 | CH51: 1 | CI51: 1 | CJ51: 1 | CK51: 1
...

Sheet Industrial ARR Rollforward
B2: Trio Mobil
B3: Industrial ARR Rollforward
C5: =C6&" " &YEAR(C8) -> Q4 2021 | D5: =D6&" " &YEAR(D8) -> Q4 2022 | E5: =E6&" " &YEAR(E8) -> Q4 2023 | F5: =F6&" " &YEAR(F8) -> Q4 2024 | G5: =G6&" " &YEAR(G8) -> TTM 2025 | I5: =I6&" " &YEAR(I8) -> Q1 2021 | J5: =J6&" " &YEAR(J8) -> Q2 2021 | K5: =K6&" " &YEAR(K8) -> Q3 2021 | L5: =L6&" " &YEAR(L8) -> Q4 2021 | M5: =M6&" " &YEAR(M8) -> Q1 2022 | N5: =N6&" " &YEAR(N8) -> Q2 2022 | O5: =O6&" " &YEAR(O8) -> Q3 2022 | P5: =P6&" " &YEAR(P8) -> Q4 2022 | ... AB5: =AB6&" " &YEAR(AB8) -> Q4 2025 | AD5: =AD6&" " &YEAR(AD8) -> Q1 2021 | AE5: =AE6&" " &YEAR(AE8) -> Q1 2021 | AF5: =AF6&" " &YEAR(AF8) -> Q1 2021 | AG5: =AG6&" " &YEAR(AG8) -> Q2 2021 | AH5: =AH6&" " &YEAR(AH8) -> Q2 2021 | AI5: =AI6&" " &YEAR(AI8) -> Q2 2021 | AJ5: =AJ6&" " &YEAR(AJ8) -> Q3 2021 | AK5: =AK6&" " &YEAR(AK8) -> Q3 2021 | ... CK5: =CK6&" " &YEAR(CK8) -> Q4 2025
C6: Q4 | D6: Q4 | E6: Q4 | F6: Q4 | G6: TTM | I6: Q1 | J6: Q2 | K6: Q3 | L6: Q4 | M6: Q1 | N6: Q2 | O6: Q3 | P6: Q4 | Q6: Q1 | R6: Q2 | S6: Q3 | T6: Q4 | U6: Q1 | V6: Q2 | W6: Q3 | X6: Q4 | Y6: Q1 | Z6: Q2 | AA6: Q3 | AB6: Q4 | AD6: Q1 | AE6: Q1 | AF6: Q1 | AG6: Q2 | AH6: Q2 | AI6: Q2 | AJ6: Q3 | AK6: Q3 | AL6: Q3 | AM6: Q4 | AN6: Q4 | AO6: Q4 | AP6: Q1 | AQ6: Q1 | AR6: Q1 | AS6: Q2 | AT6: Q2 | AU6: Q2 | AV6: Q3 | AW6: Q3 | AX6: Q3 | AY6: Q4 | AZ6: Q4 | BA6: Q4 | BB6: Q1 | BC6: Q1 | BD6: Q1 | BE6: Q2 | BF6: Q2 | BG6: Q2 | BH6: Q3 | BI6: Q3 | BJ6: Q3 | BK6: Q4 | BL6: Q4 | BM6: Q4 | BN6: Q1 | BO6: Q1 | BP6: Q1 | BQ6: Q2 | BR6: Q2 | BS6: Q2 | BT6: Q3 | BU6: Q3 | BV6: Q3 | BW6: Q4 | BX6: Q4 | BY6: Q4 | BZ6: Q1 | CA6: Q1 | CB6: Q1 | CC6: Q2 | CD6: Q2 | CE6: Q2 | CF6: Q3 | CG6: Q3 | CH6: Q3 | CI6: Q4 | CJ6: Q4 | CK6: Q4
C7: =YEAR(C8) -> 2021 | D7: =YEAR(D8) -> 2022 | E7: =YEAR(E8) -> 2023 | F7: =YEAR(F8) -> 2024 | G7: =YEAR(G8) -> 2025 | I7: =YEAR(I8) -> 2021 | J7: =YEAR(J8) -> 2021 | K7: =YEAR(K8) -> 2021 | L7: =YEAR(L8) -> 2021 | M7: =YEAR(M8) -> 2022 | N7: =YEAR(N8) -> 2022 | O7: =YEAR(O8) -> 2022 | P7: =YEAR(P8) -> 2022 | ... AB7: =YEAR(AB8) -> 2025 | AD7: =YEAR(AD8) -> 2021 | AE7: =YEAR(AE8) -> 2021 | AF7: =YEAR(AF8) -> 2021 | AG7: =YEAR(AG8) -> 2021 | AH7: =YEAR(AH8) -> 2021 | AI7: =YEAR(AI8) -> 2021 | AJ7: =YEAR(AJ8) -> 2021 | AK7: =YEAR(AK8) -> 2021 | ... CK7: =YEAR(CK8) -> 2025
B8: Industrial ARR | C8: 44561 | D8: =EOMONTH(C8,12) -> 44926 | E8: =EOMONTH(D8,12) -> 45291 | F8: =EOMONTH(E8,12) -> 45657 | G8: =EOMONTH(F8,12) -> 46022 | I8: 44286 | J8: =EOMONTH(I8,3) -> 44377 | K8: =EOMONTH(J8,3) -> 44469 | L8: =EOMONTH(K8,3) -> 44561 | M8: =EOMONTH(L8,3) -> 44651 | N8: =EOMONTH(M8,3) -> 44742 | O8: =EOMONTH(N8,3) -> 44834 | P8: =EOMONTH(O8,3) -> 44926 | Q8: =EOMONTH(P8,3) -> 45016 | ... W8: =EOMONTH(V8,3) -> 45565 | X8: 45657 | Y8: 45747 | Z8: 45838 | AA8: 45930 | AB8: 46022 | AD8: 44227 | AE8: =EOMONTH(AD8,1) -> 44255 | AF8: =EOMONTH(AE8,1) -> 44286 | AG8: =EOMONTH(AF8,1) -> 44316 | AH8: =EOMONTH(AG8,1) -> 44347 | AI8: =EOMONTH(AH8,1) -> 44377 | AJ8: =EOMONTH(AI8,1) -> 44408 | AK8: =EOMONTH(AJ8,1) -> 44439 | AL8: =EOMONTH(AK8,1) -> 44469 | ... CK8: =EOMONTH(CJ8,1) -> 46022
B9: Beginning | C9: =I9 -> 715138.93 | D9: =+SUMIFS($AD$14:$CL$14,$AD$8:$CL$8,EOMONTH(D8,-12)) -> 1014969.7 | E9: =+SUMIFS($AD$14:$CL$14,$AD$8:$CL$8,EOMONTH(E8,-12)) -> 2187670.7 | F9: =+SUMIFS($AD$14:$CL$14,$AD$8:$CL$8,EOMONTH(F8,-12)) -> 3967064.8 | G9: =+SUMIFS($AD$14:$CL$14,$AD$8:$CL$8,EOMONTH(G8,-12)) -> 5192351 | I9: =AD9 -> 715138.93 | J9: =I14 -> 781715.86 | K9: =J14 -> 775623.44 | L9: =K14 -> 922160.71 | M9: =L14 -> 1014969.7 | N9: =M14 -> 1168916.7 | O9: =N14 -> 1625005.3 | P9: =O14 -> 1863009.7 | Q9: =P14 -> 2187670.7 | ... AB9: =AA14 -> 6791032.2 | AD9: =+'MRR Schedule Summary'!C25*12 -> 715138.93 | AE9: =AD14 -> 746844.43 | AF9: =AE14 -> 757828.4 | AG9: =AF14 -> 781715.86 | AH9: =AG14 -> 781152.3 | AI9: =AH14 -> 785449.27 | AJ9: =AI14 -> 775623.44 | AK9: =AJ14 -> 772449.02 | AL9: =AK14 -> 810237.35 | ... CK9: =CJ14 -> 7060296.9
B10: (+) New | C10: =SUMIFS($I10:$W10,$I$7:$W$7,C$7) -> 196329.34 | D10: =+SUM(OFFSET(INDEX($AD10:$CL10,MATCH(D$8,$AD$8:$CL$8,0)),,,,-12)) -> 689518.12 | E10: =+SUM(OFFSET(INDEX($AD10:$CL10,MATCH(E$8,$AD$8:$CL$8,0)),,,,-12)) -> 1269931.9 | F10: =+SUM(OFFSET(INDEX($AD10:$CL10,MATCH(F$8,$AD$8:$CL$8,0)),,,,-12)) -> 692611.46 | G10: =+SUM(OFFSET(INDEX($AD10:$CL10,MATCH(G$8,$AD$8:$CL$8,0)),,,,-12)) -> 1949466.7 | I10: =SUMIFS($AD10:$BT10,$AD$5:$BT$5,I$5) -> 11404.371 | J10: =SUMIFS($AD10:$BT10,$AD$5:$BT$5,J$5) -> 20207.816 | K10: =SUMIFS($AD10:$BT10,$AD$5:$BT$5,K$5) -> 96570.778 | L10: =SUMIFS($AD10:$BT10,$AD$5:$BT$5,L$5) -> 68146.375 | M10: =SUMIFS($AD10:$BT10,$AD$5:$BT$5,M$5) -> 35675.524 | N10: =SUMIFS($AD10:$BT10,$AD$5:$BT$5,N$5) -> 348450.22 | O10: =SUMIFS($AD10:$BT10,$AD$5:$BT$5,O$5) -> 160605.37 | P10: =SUMIFS($AD10:$BT10,$AD$5:$BT$5,P$5) -> 144787.01 | ... V10: =SUMIFS($AD10:$BT10,$AD$5:$BT$5,V$5) -> 312111.98 | W10: =SUMIFS($AD10:$BV10,$AD$5:$BV$5,W$5) -> 134400.33 | X10: =SUMIFS($AD10:$BY10,$AD$5:$BY$5,X$5) -> 125274.93 | Y10: =SUMIFS($AD10:$CL10,$AD$5:$CL$5,Y$5) -> 380719.42 | Z10: =SUMIFS($AD10:$CL10,$AD$5:$CL$5,Z$5) -> 485167.65 | AA10: =SUMIFS($AD10:$CL10,$AD$5:$CL$5,AA$5) -> 492210.13 | AB10: =SUMIFS($AD10:$CL10,$AD$5:$CL$5,AB$5) -> 591369.46 | AD10: =+'MRR Schedule Summary'!C26*12 -> 4783.6505 | AE10: =+'MRR Schedule Summary'!D26*12 -> 999.24216 | AF10: =+'MRR Schedule Summary'!E26*12 -> 5621.478 | AG10: =+'MRR Schedule Summary'!F26*12 -> 8264.4457 | AH10: =+'MRR Schedule Summary'!G26*12 -> 5986.5236 | AI10: =+'MRR Schedule Summary'!H26*12 -> 5956.8469 | AJ10: =+'MRR Schedule Summary'!I26*12 -> 4144.5983 | AK10: =+'MRR Schedule Summary'!J26*12 -> 20304.577 | ... CK10: =+'MRR Schedule Summary'!BJ26*12 -> 525504.14
B11: (+) Upsell | C11: =SUMIFS($I11:$W11,$I$7:$W$7,C$7) -> 180353.86 | D11: =+SUM(OFFSET(INDEX($AD11:$CL11,MATCH(D$8,$AD$8:$CL$8,0)),,,,-12)) -> 600387.39 | E11: =+SUM(OFFSET(INDEX($AD11:$CL11,MATCH(E$8,$AD$8:$CL$8,0)),,,,-12)) -> 932402.55 | F11: =+SUM(OFFSET(INDEX($AD11:$CL11,MATCH(F$8,$AD$8:$CL$8,0)),,,,-12)) -> 1268550.8 | G11: =+SUM(OFFSET(INDEX($AD11:$CL11,MATCH(G$8,$AD$8:$CL$8,0)),,,,-12)) -> 1537459.7 | I11: =SUMIFS($AD11:$BT11,$AD$5:$BT$5,I$5) -> 55671.846 | J11: =SUMIFS($AD11:$BT11,$AD$5:$BT$5,J$5) -> 6401.0345 | K11: =SUMIFS($AD11:$BT11,$AD$5:$BT$5,K$5) -> 58576.612 | L11: =SUMIFS($AD11:$BT11,$AD$5:$BT$5,L$5) -> 59704.365 | M11: =SUMIFS($AD11:$BT11,$AD$5:$BT$5,M$5) -> 138563.3 | N11: =SUMIFS($AD11:$BT11,$AD$5:$BT$5,N$5) -> 112465.68 | O11: =SUMIFS($AD11:$BT11,$AD$5:$BT$5,O$5) -> 114339.61 | P11: =SUMIFS($AD11:$BT11,$AD$5:$BT$5,P$5) -> 235018.8 | ... V11: =SUMIFS($AD11:$BT11,$AD$5:$BT$5,V$5) -> 184206.67 | W11: =SUMIFS($AD11:$BV11,$AD$5:$BV$5,W$5) -> 381415.94 | X11: =SUMIFS($AD11:$BY11,$AD$5:$BY$5,X$5) -> 475413.71 | Y11: =SUMIFS($AD11:$CL11,$AD$5:$CL$5,Y$5) -> 184680.81 | Z11: =SUMIFS($AD11:$CL11,$AD$5:$CL$5,Z$5) -> 309203.49 | AA11: =SUMIFS($AD11:$CL11,$AD$5:$CL$5,AA$5) -> 436051.26 | AB11: =SUMIFS($AD11:$CL11,$AD$5:$CL$5,AB$5) -> 607524.15 | AD11: =+'MRR Schedule Summary'!C27*12 -> 26921.853 | AE11: =+'MRR Schedule Summary'!D27*12 -> 10484.005 | AF11: =+'MRR Schedule Summary'!E27*12 -> 18265.988 | AG11: =+'MRR Schedule Summary'!F27*12 -> 554.06422 | AH11: =+'MRR Schedule Summary'!G27*12 -> 5681.5747 | AI11: =+'MRR Schedule Summary'!H27*12 -> 165.39552 | AJ11: =+'MRR Schedule Summary'!I27*12 -> 0 | AK11: =+'MRR Schedule Summary'!J27*12 -> 18774.807 | ... CK11: =+'MRR Schedule Summary'!BJ27*12 -> 306157.87
B12: (-) Downsell | C12: =SUMIFS($I12:$W12,$I$7:$W$7,C$7) -> -76852.426 | D12: =+SUM(OFFSET(INDEX($AD12:$CL12,MATCH(D$8,$AD$8:$CL$8,0)),,,,-12)) -> -117447.59 | E12: =+SUM(OFFSET(INDEX($AD12:$CL12,MATCH(E$8,$AD$8:$CL$8,0)),,,,-12)) -> -422849.7 | F12: =+SUM(OFFSET(INDEX($AD12:$CL12,MATCH(F$8,$AD$8:$CL$8,0)),,,,-12)) -> -692489.5 | G12: =+SUM(OFFSET(INDEX($AD12:$CL12,MATCH(G$8,$AD$8:$CL$8,0)),,,,-12)) -> -795946.71 | I12: =SUMIFS($AD12:$BT12,$AD$5:$BT$5,I$5) -> -499.27795 | J12: =SUMIFS($AD12:$BT12,$AD$5:$BT$5,J$5) -> -32701.271 | K12: =SUMIFS($AD12:$BT12,$AD$5:$BT$5,K$5) -> -8610.1241 | L12: =SUMIFS($AD12:$BT12,$AD$5:$BT$5,L$5) -> -35041.753 | M12: =SUMIFS($AD12:$BT12,$AD$5:$BT$5,M$5) -> -20235.908 | N12: =SUMIFS($AD12:$BT12,$AD$5:$BT$5,N$5) -> -4827.2256 | O12: =SUMIFS($AD12:$BT12,$AD$5:$BT$5,O$5) -> -36940.637 | P12: =SUMIFS($AD12:$BT12,$AD$5:$BT$5,P$5) -> -55443.819 | ... V12: =SUMIFS($AD12:$BT12,$AD$5:$BT$5,V$5) -> -161200.29 | W12: =SUMIFS($AD12:$BV12,$AD$5:$BV$5,W$5) -> -160646.5 | X12: =SUMIFS($AD12:$BY12,$AD$5:$BY$5,X$5) -> -255558.61 | Y12: =SUMIFS($AD12:$CL12,$AD$5:$CL$5,Y$5) -> -120526.72 | Z12: =SUMIFS($AD12:$CL12,$AD$5:$CL$5,Z$5) -> -373478.15 | AA12: =SUMIFS($AD12:$CL12,$AD$5:$CL$5,AA$5) -> -153389.81 | AB12: =SUMIFS($AD12:$CL12,$AD$5:$CL$5,AB$5) -> -148552.02 | AD12: =+'MRR Schedule Summary'!C28*12 -> 0 | AE12: =+'MRR Schedule Summary'!D28*12 -> -499.27795 | AF12: =+'MRR Schedule Summary'!E28*12 -> 0 | AG12: =+'MRR Schedule Summary'!F28*12 -> -9382.0784 | AH12: =+'MRR Schedule Summary'!G28*12 -> -7371.1291 | AI12: =+'MRR Schedule Summary'!H28*12 -> -15948.063 | AJ12: =+'MRR Schedule Summary'!I28*12 -> -7319.0261 | AK12: =+'MRR Schedule Summary'!J28*12 -> -1291.0552 | ... CK12: =+'MRR Schedule Summary'!BJ28*12 -> -55296.726
B13: (-) Churn | C13: =SUMIFS($I13:$W13,$I$7:$W$7,C$7) -> 0 | D13: =+SUM(OFFSET(INDEX($AD13:$CL13,MATCH(D$8,$AD$8:$CL$8,0)),,,,-12)) -> 243.0354 | E13: =+SUM(OFFSET(INDEX($AD13:$CL13,MATCH(E$8,$AD$8:$CL$8,0)),,,,-12)) -> -90.686478 | F13: =+SUM(OFFSET(INDEX($AD13:$CL13,MATCH(F$8,$AD$8:$CL$8,0)),,,,-12)) -> -43386.467 | G13: =+SUM(OFFSET(INDEX($AD13:$CL13,MATCH(G$8,$AD$8:$CL$8,0)),,,,-12)) -> -51718.687 | I13: =SUMIFS($AD13:$BT13,$AD$5:$BT$5,I$5) -> 0 | J13: =SUMIFS($AD13:$BT13,$AD$5:$BT$5,J$5) -> 0 | K13: =SUMIFS($AD13:$BT13,$AD$5:$BT$5,K$5) -> 0 | L13: =SUMIFS($AD13:$BT13,$AD$5:$BT$5,L$5) -> 0 | M13: =SUMIFS($AD13:$BT13,$AD$5:$BT$5,M$5) -> -55.938596 | N13: =SUMIFS($AD13:$BT13,$AD$5:$BT$5,N$5) -> 0 | O13: =SUMIFS($AD13:$BT13,$AD$5:$BT$5,O$5) -> 0 | P13: =SUMIFS($AD13:$BT13,$AD$5:$BT$5,P$5) -> 298.974 | ... V13: =SUMIFS($AD13:$BT13,$AD$5:$BT$5,V$5) -> -11542.33 | W13: =SUMIFS($AD13:$BV13,$AD$5:$BV$5,W$5) -> -19527.517 | X13: =SUMIFS($AD13:$BY13,$AD$5:$BY$5,X$5) -> -8653.5513 | Y13: =SUMIFS($AD13:$CL13,$AD$5:$CL$5,Y$5) -> -3998.2247 | Z13: =SUMIFS($AD13:$CL13,$AD$5:$CL$5,Z$5) -> -27953.71 | AA13: =SUMIFS($AD13:$CL13,$AD$5:$CL$5,AA$5) -> -10004.936 | AB13: =SUMIFS($AD13:$CL13,$AD$5:$CL$5,AB$5) -> -9761.8169 | AD13: =+SUM('MRR Schedule Summary'!C29:C30)*12 -> 0 | AE13: =+SUM('MRR Schedule Summary'!D29:D30)*12 -> 0 | AF13: =+SUM('MRR Schedule Summary'!E29:E30)*12 -> 0 | AG13: =+SUM('MRR Schedule Summary'!F29:F30)*12 -> 0 | AH13: =+SUM('MRR Schedule Summary'!G29:G30)*12 -> 0 | AI13: =+SUM('MRR Schedule Summary'!H29:H30)*12 -> 0 | AJ13: =+SUM('MRR Schedule Summary'!I29:I30)*12 -> 0 | AK13: =+SUM('MRR Schedule Summary'!J29:J30)*12 -> 0 | ... CK13: =+SUM('MRR Schedule Summary'!BJ29:BJ30)*12 -> -5050.1849
B14: Ending ARR | C14: =SUM(C9:C13) -> 1014969.7 | D14: =SUM(D9:D13) -> 2187670.7 | E14: =SUM(E9:E13) -> 3967064.8 | F14: =SUM(F9:F13) -> 5192351 | G14: =SUM(G9:G13) -> 7831612 | I14: =SUM(I9:I13) -> 781715.86 | J14: =SUM(J9:J13) -> 775623.44 | K14: =SUM(K9:K13) -> 922160.71 | L14: =SUM(L9:L13) -> 1014969.7 | M14: =SUM(M9:M13) -> 1168916.7 | N14: =SUM(N9:N13) -> 1625005.3 | O14: =SUM(O9:O13) -> 1863009.7 | P14: =SUM(P9:P13) -> 2187670.7 | ... AB14: =SUM(AB9:AB13) -> 7831612 | AD14: =SUM(AD9:AD13) -> 746844.43 | AE14: =SUM(AE9:AE13) -> 757828.4 | AF14: =SUM(AF9:AF13) -> 781715.86 | AG14: =SUM(AG9:AG13) -> 781152.3 | AH14: =SUM(AH9:AH13) -> 785449.27 | AI14: =SUM(AI9:AI13) -> 775623.44 | AJ14: =SUM(AJ9:AJ13) -> 772449.02 | AK14: =SUM(AK9:AK13) -> 810237.35 | ... CK14: =SUM(CK9:CK13) -> 7831612
B15: % YoY Growth | D15: =D14/C14-1 -> 1.1554049 | E15: =E14/D14-1 -> 0.81337385 | F15: =F14/E14-1 -> 0.30886471 | G15: =G14/G9-1 -> 0.50829787 | M15: =M14/I14-1 -> 0.49532167 | N15: =N14/J14-1 -> 1.0950957 | O15: =O14/K14-1 -> 1.0202657 | P15: =P14/L14-1 -> 1.1554049 | Q15: =Q14/M14-1 -> 0.96645628 | R15: =R14/N14-1 -> 0.66216196 | S15: =S14/O14-1 -> 0.89889119 | T15: =T14/P14-1 -> 0.81337385 | ... AB15: =AB14/X14-1 -> 0.50829787 | AP15: =AP14/AD14-1 -> 0.37779984 | AQ15: =AQ14/AE14-1 -> 0.40472056 | AR15: =AR14/AF14-1 -> 0.49532167 | AS15: =AS14/AG14-1 -> 0.69660208 | AT15: =AT14/AH14-1 -> 0.86610121 | AU15: =AU14/AI14-1 -> 1.0950957 | AV15: =AV14/AJ14-1 -> 1.2312077 | AW15: =AW14/AK14-1 -> 1.1558327 | ... CK15: =CK14/BY14-1 -> 0.50829787
B17: Gross Retention (c only) | C17: =1+C13/C9 -> 1 | D17: =1+D13/D9 -> 1.0002395 | E17: =1+E13/E9 -> 0.99995855 | F17: =1+F13/F9 -> 0.98906333 | G17: =1+G13/G9 -> 0.99003945 | I17: =1+I13*4/I9 -> 1 | J17: =1+J13*4/J9 -> 1 | K17: =1+K13*4/K9 -> 1 | L17: =1+L13*4/L9 -> 1 | M17: =1+M13*4/M9 -> 0.99977955 | N17: =1+N13*4/N9 -> 1 | O17: =1+O13*4/O9 -> 1 | P17: =1+P13*4/P9 -> 1.0006419 | ... AB17: =1+AB13*4/AB9 -> 0.99425017 | AE17: =1+AE13*12/AE9 -> 1 | AF17: =1+AF13*12/AF9 -> 1 | AG17: =1+AG13*12/AG9 -> 1 | AH17: =1+AH13*12/AH9 -> 1 | AI17: =1+AI13*12/AI9 -> 1 | AJ17: =1+AJ13*12/AJ9 -> 1 | AK17: =1+AK13*12/AK9 -> 1 | AL17: =1+AL13*12/AL9 -> 1 | ... CK17: =1+CK13*12/CK9 -> 0.99141648
B18: Gross Retention (c + d) | C18: =1+SUM(C12:C13)/C9 -> 0.89253497 | D18: =1+SUM(D12:D13)/D9 -> 0.88452409 | E18: =1+SUM(E12:E13)/E9 -> 0.8066709 | F18: =1+SUM(F12:F13)/F9 -> 0.81450367 | G18: =1+SUM(G12:G13)/G9 -> 0.83674729 | I18: =1+SUM(I12:I13)*4/I9 -> 0.99720738 | J18: =1+SUM(J12:J13)*4/J9 -> 0.83266928 | K18: =1+SUM(K12:K13)*4/K9 -> 0.95559637 | L18: =1+SUM(L12:L13)*4/L9 -> 0.84800153 | M18: =1+SUM(M12:M13)*4/M9 -> 0.92002974 | N18: =1+SUM(N12:N13)*4/N9 -> 0.98348137 | O18: =1+SUM(O12:O13)*4/O9 -> 0.9090695 | P18: =1+SUM(P12:P13)*4/P9 -> 0.88160052 | ... AB18: =1+SUM(AB12:AB13)*4/AB9 -> 0.90675124 | AE18: =1+SUM(AE12:AE13)*12/AE9 -> 0.9919778 | AF18: =1+SUM(AF12:AF13)*12/AF9 -> 1 | AG18: =1+SUM(AG12:AG13)*12/AG9 -> 0.85597716 | AH18: =1+SUM(AH12:AH13)*12/AH9 -> 0.8867653 | AI18: =1+SUM(AI12:AI13)*12/AI9 -> 0.7563474 | AJ18: =1+SUM(AJ12:AJ13)*12/AJ9 -> 0.88676424 | AK18: =1+SUM(AK12:AK13)*12/AK9 -> 0.97994345 | AL18: =1+SUM(AL12:AL13)*12/AL9 -> 0.99999937 | ... CK18: =1+SUM(CK12:CK13)*12/CK9 -> 0.89743166
B19: Net Retention | C19: =1+SUM(C11:C13)/C9 -> 1.1447291 | D19: =1+SUM(D11:D13)/D9 -> 1.4760564 | E19: =1+SUM(E11:E13)/E9 -> 1.2328788 | F19: =1+SUM(F11:F13)/F9 -> 1.1342743 | G19: =1+SUM(G11:G13)/G9 -> 1.1328482 | I19: =1+SUM(I11:I13)*4/I9 -> 1.3085978 | J19: =1+SUM(J11:J13)*4/J9 -> 0.86542304 | K19: =1+SUM(K11:K13)*4/K9 -> 1.2576843 | L19: =1+SUM(L11:L13)*4/L9 -> 1.1069775 | M19: =1+SUM(M11:M13)*4/M9 -> 1.4661083 | N19: =1+SUM(N11:N13)*4/N9 -> 1.3683358 | O19: =1+SUM(O11:O13)*4/O9 -> 1.1905199 | P19: =1+SUM(P11:P13)*4/P9 -> 1.3862008 | ... AB19: =1+SUM(AB11:AB13)*4/AB9 -> 1.2645903 | AE19: =1+SUM(AE11:AE13)*12/AE9 -> 1.1604306 | AF19: =1+SUM(AF11:AF13)*12/AF9 -> 1.2892368 | AG19: =1+SUM(AG11:AG13)*12/AG9 -> 0.86448251 | AH19: =1+SUM(AH11:AH13)*12/AH9 -> 0.9740452 | AI19: =1+SUM(AI11:AI13)*12/AI9 -> 0.75887429 | AJ19: =1+SUM(AJ11:AJ13)*12/AJ9 -> 0.88676424 | AK19: =1+SUM(AK11:AK13)*12/AK9 -> 1.2716102 | AL19: =1+SUM(AL11:AL13)*12/AL9 -> 1.589483 | ... CK19: =1+SUM(CK11:CK13)*12/CK9 -> 1.4177914
B21: Net New ARR | C21: =SUM(C10:C13) -> 299830.77 | D21: =SUM(D10:D13) -> 1172701 | E21: =SUM(E10:E13) -> 1779394.1 | F21: =SUM(F10:F13) -> 1225286.3 | G21: =SUM(G10:G13) -> 2639261 | I21: =SUM(I10:I13) -> 66576.938 | J21: =SUM(J10:J13) -> -6092.4199 | K21: =SUM(K10:K13) -> 146537.27 | L21: =SUM(L10:L13) -> 92808.986 | M21: =SUM(M10:M13) -> 153946.98 | N21: =SUM(N10:N13) -> 456088.67 | O21: =SUM(O10:O13) -> 238004.35 | P21: =SUM(P10:P13) -> 324660.96 | ... AB21: =SUM(AB10:AB13) -> 1040579.8 | AE21: =SUM(AE10:AE13) -> 10983.969 | AF21: =SUM(AF10:AF13) -> 23887.466 | AG21: =SUM(AG10:AG13) -> -563.56844 | AH21: =SUM(AH10:AH13) -> 4296.9692 | AI21: =SUM(AI10:AI13) -> -9825.8207 | AJ21: =SUM(AJ10:AJ13) -> -3174.4278 | AK21: =SUM(AK10:AK13) -> 37788.329 | AL21: =SUM(AL10:AL13) -> 111923.36 | ... CK21: =SUM(CK10:CK13) -> 771315.1
B22: New + Upsell | C22: =SUM(C10:C11) -> 376683.2 | D22: =SUM(D10:D11) -> 1289905.5 | E22: =SUM(E10:E11) -> 2202334.5 | F22: =SUM(F10:F11) -> 1961162.3 | G22: =SUM(G10:G11) -> 3486926.4 | I22: =SUM(I10:I11) -> 67076.216 | J22: =SUM(J10:J11) -> 26608.851 | K22: =SUM(K10:K11) -> 155147.39 | L22: =SUM(L10:L11) -> 127850.74 | M22: =SUM(M10:M11) -> 174238.83 | N22: =SUM(N10:N11) -> 460915.89 | O22: =SUM(O10:O11) -> 274944.98 | P22: =SUM(P10:P11) -> 379805.81 | ... AB22: =SUM(AB10:AB11) -> 1198893.6 | AE22: =SUM(AE10:AE11) -> 11483.247 | AF22: =SUM(AF10:AF11) -> 23887.466 | AG22: =SUM(AG10:AG11) -> 8818.5099 | AH22: =SUM(AH10:AH11) -> 11668.098 | AI22: =SUM(AI10:AI11) -> 6122.2424 | AJ22: =SUM(AJ10:AJ11) -> 4144.5983 | AK22: =SUM(AK10:AK11) -> 39079.384 | AL22: =SUM(AL10:AL11) -> 111923.41 | ... CK22: =SUM(CK10:CK11) -> 831662.01
B24: Customer Count
